[ERROR] 2025-02-20 04:53:35,461 log - Internal Server Error: /aplicatie_exemplu/oferta/
Traceback (most recent call last):
  File "C:\Users\Maryo\virtualEnv\venv1\Lib\site-packages\django\core\handlers\exception.py", line 55, in inner
    response = get_response(request)
               ^^^^^^^^^^^^^^^^^^^^^
  File "C:\Users\Maryo\virtualEnv\venv1\Lib\site-packages\django\core\handlers\base.py", line 197, in _get_response
    response = wrapped_callback(request, *callback_args, **callback_kwargs)
               ^^^^^^^^^^^^^^^^^^^^^^^^^^^^^^^^^^^^^^^^^^^^^^^^^^^^^^^^^^^^
  File "C:\Users\Maryo\virtualEnv\venv1\Lib\site-packages\django\contrib\auth\decorators.py", line 60, in _view_wrapper
    return view_func(request, *args, **kwargs)
           ^^^^^^^^^^^^^^^^^^^^^^^^^^^^^^^^^^^
  File "C:\Users\Maryo\proiectDjangolaBune\aplicatie_exemplu\views.py", line 442, in oferta
    return render(request, "403.html", {
           ^^^^^^^^^^^^^^^^^^^^^^^^^^^^^
  File "C:\Users\Maryo\virtualEnv\venv1\Lib\site-packages\django\shortcuts.py", line 25, in render
    content = loader.render_to_string(template_name, context, request, using=using)
              ^^^^^^^^^^^^^^^^^^^^^^^^^^^^^^^^^^^^^^^^^^^^^^^^^^^^^^^^^^^^^^^^^^^^^
  File "C:\Users\Maryo\virtualEnv\venv1\Lib\site-packages\django\template\loader.py", line 62, in render_to_string
    return template.render(context, request)
           ^^^^^^^^^^^^^^^^^^^^^^^^^^^^^^^^^
  File "C:\Users\Maryo\virtualEnv\venv1\Lib\site-packages\django\template\backends\django.py", line 107, in render
    return self.template.render(context)
           ^^^^^^^^^^^^^^^^^^^^^^^^^^^^^
  File "C:\Users\Maryo\virtualEnv\venv1\Lib\site-packages\django\template\base.py", line 171, in render
    return self._render(context)
           ^^^^^^^^^^^^^^^^^^^^^
  File "C:\Users\Maryo\virtualEnv\venv1\Lib\site-packages\django\template\base.py", line 163, in _render
    return self.nodelist.render(context)
           ^^^^^^^^^^^^^^^^^^^^^^^^^^^^^
  File "C:\Users\Maryo\virtualEnv\venv1\Lib\site-packages\django\template\base.py", line 1008, in render
    return SafeString("".join([node.render_annotated(context) for node in self]))
                               ^^^^^^^^^^^^^^^^^^^^^^^^^^^^^^
  File "C:\Users\Maryo\virtualEnv\venv1\Lib\site-packages\django\template\base.py", line 969, in render_annotated
    return self.render(context)
           ^^^^^^^^^^^^^^^^^^^^
  File "C:\Users\Maryo\virtualEnv\venv1\Lib\site-packages\django\template\defaulttags.py", line 480, in render
    url = reverse(view_name, args=args, kwargs=kwargs, current_app=current_app)
          ^^^^^^^^^^^^^^^^^^^^^^^^^^^^^^^^^^^^^^^^^^^^^^^^^^^^^^^^^^^^^^^^^^^^^
  File "C:\Users\Maryo\virtualEnv\venv1\Lib\site-packages\django\urls\base.py", line 88, in reverse
    return resolver._reverse_with_prefix(view, prefix, *args, **kwargs)
           ^^^^^^^^^^^^^^^^^^^^^^^^^^^^^^^^^^^^^^^^^^^^^^^^^^^^^^^^^^^^
  File "C:\Users\Maryo\virtualEnv\venv1\Lib\site-packages\django\urls\resolvers.py", line 831, in _reverse_with_prefix
    raise NoReverseMatch(msg)
django.urls.exceptions.NoReverseMatch: Reverse for 'home' not found. 'home' is not a valid view function or pattern name.
[ERROR] 2025-02-20 04:53:35,461 basehttp - "GET /aplicatie_exemplu/oferta/ HTTP/1.1" 500 121833
[ERROR] 2025-02-20 05:15:49,444 log - Internal Server Error: /aplicatie_exemplu/
Traceback (most recent call last):
  File "C:\Users\Maryo\virtualEnv\venv1\Lib\site-packages\django\core\handlers\exception.py", line 55, in inner
    response = get_response(request)
               ^^^^^^^^^^^^^^^^^^^^^
  File "C:\Users\Maryo\virtualEnv\venv1\Lib\site-packages\django\core\handlers\base.py", line 197, in _get_response
    response = wrapped_callback(request, *callback_args, **callback_kwargs)
               ^^^^^^^^^^^^^^^^^^^^^^^^^^^^^^^^^^^^^^^^^^^^^^^^^^^^^^^^^^^^
  File "C:\Users\Maryo\proiectDjangolaBune\aplicatie_exemplu\views.py", line 455, in home
    return render(request, 'home.html')
           ^^^^^^^^^^^^^^^^^^^^^^^^^^^^
  File "C:\Users\Maryo\virtualEnv\venv1\Lib\site-packages\django\shortcuts.py", line 25, in render
    content = loader.render_to_string(template_name, context, request, using=using)
              ^^^^^^^^^^^^^^^^^^^^^^^^^^^^^^^^^^^^^^^^^^^^^^^^^^^^^^^^^^^^^^^^^^^^^
  File "C:\Users\Maryo\virtualEnv\venv1\Lib\site-packages\django\template\loader.py", line 61, in render_to_string
    template = get_template(template_name, using=using)
               ^^^^^^^^^^^^^^^^^^^^^^^^^^^^^^^^^^^^^^^^
  File "C:\Users\Maryo\virtualEnv\venv1\Lib\site-packages\django\template\loader.py", line 19, in get_template
    raise TemplateDoesNotExist(template_name, chain=chain)
django.template.exceptions.TemplateDoesNotExist: home.html
[ERROR] 2025-02-20 05:15:49,444 basehttp - "GET /aplicatie_exemplu/ HTTP/1.1" 500 80918
[ERROR] 2025-02-20 07:55:34,526 log - Internal Server Error: /aplicatie_exemplu/contact/
Traceback (most recent call last):
  File "C:\Users\Maryo\virtualEnv\venv1\Lib\site-packages\django\core\handlers\exception.py", line 55, in inner
    response = get_response(request)
               ^^^^^^^^^^^^^^^^^^^^^
  File "C:\Users\Maryo\virtualEnv\venv1\Lib\site-packages\django\core\handlers\base.py", line 197, in _get_response
    response = wrapped_callback(request, *callback_args, **callback_kwargs)
               ^^^^^^^^^^^^^^^^^^^^^^^^^^^^^^^^^^^^^^^^^^^^^^^^^^^^^^^^^^^^
  File "C:\Users\Maryo\proiectDjangolaBune\aplicatie_exemplu\views.py", line 84, in contact_view
    return render(request, 'contact_success.html')  # Pagina de succes
           ^^^^^^^^^^^^^^^^^^^^^^^^^^^^^^^^^^^^^^^
  File "C:\Users\Maryo\virtualEnv\venv1\Lib\site-packages\django\shortcuts.py", line 25, in render
    content = loader.render_to_string(template_name, context, request, using=using)
              ^^^^^^^^^^^^^^^^^^^^^^^^^^^^^^^^^^^^^^^^^^^^^^^^^^^^^^^^^^^^^^^^^^^^^
  File "C:\Users\Maryo\virtualEnv\venv1\Lib\site-packages\django\template\loader.py", line 61, in render_to_string
    template = get_template(template_name, using=using)
               ^^^^^^^^^^^^^^^^^^^^^^^^^^^^^^^^^^^^^^^^
  File "C:\Users\Maryo\virtualEnv\venv1\Lib\site-packages\django\template\loader.py", line 19, in get_template
    raise TemplateDoesNotExist(template_name, chain=chain)
django.template.exceptions.TemplateDoesNotExist: contact_success.html
[ERROR] 2025-02-20 07:55:34,526 basehttp - "POST /aplicatie_exemplu/contact/ HTTP/1.1" 500 84780
[ERROR] 2025-02-20 08:05:00,190 log - Internal Server Error: /aplicatie_exemplu/contact/
Traceback (most recent call last):
  File "C:\Users\Maryo\virtualEnv\venv1\Lib\site-packages\django\core\handlers\exception.py", line 55, in inner
    response = get_response(request)
               ^^^^^^^^^^^^^^^^^^^^^
  File "C:\Users\Maryo\virtualEnv\venv1\Lib\site-packages\django\core\handlers\base.py", line 197, in _get_response
    response = wrapped_callback(request, *callback_args, **callback_kwargs)
               ^^^^^^^^^^^^^^^^^^^^^^^^^^^^^^^^^^^^^^^^^^^^^^^^^^^^^^^^^^^^
  File "C:\Users\Maryo\proiectDjangolaBune\aplicatie_exemplu\views.py", line 84, in contact_view
    return render(request, 'contact_success.html')  # Pagina de succes
           ^^^^^^^^^^^^^^^^^^^^^^^^^^^^^^^^^^^^^^^
  File "C:\Users\Maryo\virtualEnv\venv1\Lib\site-packages\django\shortcuts.py", line 25, in render
    content = loader.render_to_string(template_name, context, request, using=using)
              ^^^^^^^^^^^^^^^^^^^^^^^^^^^^^^^^^^^^^^^^^^^^^^^^^^^^^^^^^^^^^^^^^^^^^
  File "C:\Users\Maryo\virtualEnv\venv1\Lib\site-packages\django\template\loader.py", line 61, in render_to_string
    template = get_template(template_name, using=using)
               ^^^^^^^^^^^^^^^^^^^^^^^^^^^^^^^^^^^^^^^^
  File "C:\Users\Maryo\virtualEnv\venv1\Lib\site-packages\django\template\loader.py", line 19, in get_template
    raise TemplateDoesNotExist(template_name, chain=chain)
django.template.exceptions.TemplateDoesNotExist: contact_success.html
[ERROR] 2025-02-20 08:05:00,190 basehttp - "POST /aplicatie_exemplu/contact/ HTTP/1.1" 500 84794
[ERROR] 2025-02-20 08:48:09,941 log - Internal Server Error: /aplicatie_exemplu/register/
Traceback (most recent call last):
  File "C:\Users\Maryo\virtualEnv\venv1\Lib\site-packages\django\db\backends\utils.py", line 105, in _execute
    return self.cursor.execute(sql, params)
           ^^^^^^^^^^^^^^^^^^^^^^^^^^^^^^^^
psycopg2.errors.UniqueViolation: duplicate key value violates unique constraint "custom_user_phone_number_key"
DETAIL:  Key (phone_number)=(0728646900) already exists.


The above exception was the direct cause of the following exception:

Traceback (most recent call last):
  File "C:\Users\Maryo\virtualEnv\venv1\Lib\site-packages\django\core\handlers\exception.py", line 55, in inner
    response = get_response(request)
               ^^^^^^^^^^^^^^^^^^^^^
  File "C:\Users\Maryo\virtualEnv\venv1\Lib\site-packages\django\core\handlers\base.py", line 197, in _get_response
    response = wrapped_callback(request, *callback_args, **callback_kwargs)
               ^^^^^^^^^^^^^^^^^^^^^^^^^^^^^^^^^^^^^^^^^^^^^^^^^^^^^^^^^^^^
  File "C:\Users\Maryo\proiectDjangolaBune\aplicatie_exemplu\views.py", line 157, in register
    user.save()
  File "C:\Users\Maryo\virtualEnv\venv1\Lib\site-packages\django\contrib\auth\base_user.py", line 62, in save
    super().save(*args, **kwargs)
  File "C:\Users\Maryo\virtualEnv\venv1\Lib\site-packages\django\db\models\base.py", line 892, in save
    self.save_base(
  File "C:\Users\Maryo\virtualEnv\venv1\Lib\site-packages\django\db\models\base.py", line 998, in save_base
    updated = self._save_table(
              ^^^^^^^^^^^^^^^^^
  File "C:\Users\Maryo\virtualEnv\venv1\Lib\site-packages\django\db\models\base.py", line 1161, in _save_table
    results = self._do_insert(
              ^^^^^^^^^^^^^^^^
  File "C:\Users\Maryo\virtualEnv\venv1\Lib\site-packages\django\db\models\base.py", line 1202, in _do_insert
    return manager._insert(
           ^^^^^^^^^^^^^^^^
  File "C:\Users\Maryo\virtualEnv\venv1\Lib\site-packages\django\db\models\manager.py", line 87, in manager_method
    return getattr(self.get_queryset(), name)(*args, **kwargs)
           ^^^^^^^^^^^^^^^^^^^^^^^^^^^^^^^^^^^^^^^^^^^^^^^^^^^
  File "C:\Users\Maryo\virtualEnv\venv1\Lib\site-packages\django\db\models\query.py", line 1847, in _insert
    return query.get_compiler(using=using).execute_sql(returning_fields)
           ^^^^^^^^^^^^^^^^^^^^^^^^^^^^^^^^^^^^^^^^^^^^^^^^^^^^^^^^^^^^^
  File "C:\Users\Maryo\virtualEnv\venv1\Lib\site-packages\django\db\models\sql\compiler.py", line 1836, in execute_sql
    cursor.execute(sql, params)
  File "C:\Users\Maryo\virtualEnv\venv1\Lib\site-packages\django\db\backends\utils.py", line 122, in execute
    return super().execute(sql, params)
           ^^^^^^^^^^^^^^^^^^^^^^^^^^^^
  File "C:\Users\Maryo\virtualEnv\venv1\Lib\site-packages\django\db\backends\utils.py", line 79, in execute
    return self._execute_with_wrappers(
           ^^^^^^^^^^^^^^^^^^^^^^^^^^^^
  File "C:\Users\Maryo\virtualEnv\venv1\Lib\site-packages\django\db\backends\utils.py", line 92, in _execute_with_wrappers
    return executor(sql, params, many, context)
           ^^^^^^^^^^^^^^^^^^^^^^^^^^^^^^^^^^^^
  File "C:\Users\Maryo\virtualEnv\venv1\Lib\site-packages\django\db\backends\utils.py", line 100, in _execute
    with self.db.wrap_database_errors:
  File "C:\Users\Maryo\virtualEnv\venv1\Lib\site-packages\django\db\utils.py", line 91, in __exit__
    raise dj_exc_value.with_traceback(traceback) from exc_value
  File "C:\Users\Maryo\virtualEnv\venv1\Lib\site-packages\django\db\backends\utils.py", line 105, in _execute
    return self.cursor.execute(sql, params)
           ^^^^^^^^^^^^^^^^^^^^^^^^^^^^^^^^
django.db.utils.IntegrityError: duplicate key value violates unique constraint "custom_user_phone_number_key"
DETAIL:  Key (phone_number)=(0728646900) already exists.

[ERROR] 2025-02-20 08:48:09,950 basehttp - "POST /aplicatie_exemplu/register/ HTTP/1.1" 500 157360
[ERROR] 2025-02-20 08:48:22,236 log - Internal Server Error: /aplicatie_exemplu/register/
Traceback (most recent call last):
  File "C:\Users\Maryo\virtualEnv\venv1\Lib\site-packages\django\db\backends\utils.py", line 105, in _execute
    return self.cursor.execute(sql, params)
           ^^^^^^^^^^^^^^^^^^^^^^^^^^^^^^^^
psycopg2.errors.UniqueViolation: duplicate key value violates unique constraint "custom_user_username_key"
DETAIL:  Key (username)=(maryo100) already exists.


The above exception was the direct cause of the following exception:

Traceback (most recent call last):
  File "C:\Users\Maryo\virtualEnv\venv1\Lib\site-packages\django\core\handlers\exception.py", line 55, in inner
    response = get_response(request)
               ^^^^^^^^^^^^^^^^^^^^^
  File "C:\Users\Maryo\virtualEnv\venv1\Lib\site-packages\django\core\handlers\base.py", line 197, in _get_response
    response = wrapped_callback(request, *callback_args, **callback_kwargs)
               ^^^^^^^^^^^^^^^^^^^^^^^^^^^^^^^^^^^^^^^^^^^^^^^^^^^^^^^^^^^^
  File "C:\Users\Maryo\proiectDjangolaBune\aplicatie_exemplu\views.py", line 157, in register
    user.save()
  File "C:\Users\Maryo\virtualEnv\venv1\Lib\site-packages\django\contrib\auth\base_user.py", line 62, in save
    super().save(*args, **kwargs)
  File "C:\Users\Maryo\virtualEnv\venv1\Lib\site-packages\django\db\models\base.py", line 892, in save
    self.save_base(
  File "C:\Users\Maryo\virtualEnv\venv1\Lib\site-packages\django\db\models\base.py", line 998, in save_base
    updated = self._save_table(
              ^^^^^^^^^^^^^^^^^
  File "C:\Users\Maryo\virtualEnv\venv1\Lib\site-packages\django\db\models\base.py", line 1161, in _save_table
    results = self._do_insert(
              ^^^^^^^^^^^^^^^^
  File "C:\Users\Maryo\virtualEnv\venv1\Lib\site-packages\django\db\models\base.py", line 1202, in _do_insert
    return manager._insert(
           ^^^^^^^^^^^^^^^^
  File "C:\Users\Maryo\virtualEnv\venv1\Lib\site-packages\django\db\models\manager.py", line 87, in manager_method
    return getattr(self.get_queryset(), name)(*args, **kwargs)
           ^^^^^^^^^^^^^^^^^^^^^^^^^^^^^^^^^^^^^^^^^^^^^^^^^^^
  File "C:\Users\Maryo\virtualEnv\venv1\Lib\site-packages\django\db\models\query.py", line 1847, in _insert
    return query.get_compiler(using=using).execute_sql(returning_fields)
           ^^^^^^^^^^^^^^^^^^^^^^^^^^^^^^^^^^^^^^^^^^^^^^^^^^^^^^^^^^^^^
  File "C:\Users\Maryo\virtualEnv\venv1\Lib\site-packages\django\db\models\sql\compiler.py", line 1836, in execute_sql
    cursor.execute(sql, params)
  File "C:\Users\Maryo\virtualEnv\venv1\Lib\site-packages\django\db\backends\utils.py", line 122, in execute
    return super().execute(sql, params)
           ^^^^^^^^^^^^^^^^^^^^^^^^^^^^
  File "C:\Users\Maryo\virtualEnv\venv1\Lib\site-packages\django\db\backends\utils.py", line 79, in execute
    return self._execute_with_wrappers(
           ^^^^^^^^^^^^^^^^^^^^^^^^^^^^
  File "C:\Users\Maryo\virtualEnv\venv1\Lib\site-packages\django\db\backends\utils.py", line 92, in _execute_with_wrappers
    return executor(sql, params, many, context)
           ^^^^^^^^^^^^^^^^^^^^^^^^^^^^^^^^^^^^
  File "C:\Users\Maryo\virtualEnv\venv1\Lib\site-packages\django\db\backends\utils.py", line 100, in _execute
    with self.db.wrap_database_errors:
  File "C:\Users\Maryo\virtualEnv\venv1\Lib\site-packages\django\db\utils.py", line 91, in __exit__
    raise dj_exc_value.with_traceback(traceback) from exc_value
  File "C:\Users\Maryo\virtualEnv\venv1\Lib\site-packages\django\db\backends\utils.py", line 105, in _execute
    return self.cursor.execute(sql, params)
           ^^^^^^^^^^^^^^^^^^^^^^^^^^^^^^^^
django.db.utils.IntegrityError: duplicate key value violates unique constraint "custom_user_username_key"
DETAIL:  Key (username)=(maryo100) already exists.

[ERROR] 2025-02-20 08:48:22,243 basehttp - "POST /aplicatie_exemplu/register/ HTTP/1.1" 500 157301
[ERROR] 2025-02-20 08:48:22,298 log - Internal Server Error: /aplicatie_exemplu/register/
Traceback (most recent call last):
  File "C:\Users\Maryo\virtualEnv\venv1\Lib\site-packages\django\db\backends\utils.py", line 105, in _execute
    return self.cursor.execute(sql, params)
           ^^^^^^^^^^^^^^^^^^^^^^^^^^^^^^^^
psycopg2.errors.UniqueViolation: duplicate key value violates unique constraint "custom_user_username_key"
DETAIL:  Key (username)=(maryo100) already exists.


The above exception was the direct cause of the following exception:

Traceback (most recent call last):
  File "C:\Users\Maryo\virtualEnv\venv1\Lib\site-packages\django\core\handlers\exception.py", line 55, in inner
    response = get_response(request)
               ^^^^^^^^^^^^^^^^^^^^^
  File "C:\Users\Maryo\virtualEnv\venv1\Lib\site-packages\django\core\handlers\base.py", line 197, in _get_response
    response = wrapped_callback(request, *callback_args, **callback_kwargs)
               ^^^^^^^^^^^^^^^^^^^^^^^^^^^^^^^^^^^^^^^^^^^^^^^^^^^^^^^^^^^^
  File "C:\Users\Maryo\proiectDjangolaBune\aplicatie_exemplu\views.py", line 157, in register
    user.save()
  File "C:\Users\Maryo\virtualEnv\venv1\Lib\site-packages\django\contrib\auth\base_user.py", line 62, in save
    super().save(*args, **kwargs)
  File "C:\Users\Maryo\virtualEnv\venv1\Lib\site-packages\django\db\models\base.py", line 892, in save
    self.save_base(
  File "C:\Users\Maryo\virtualEnv\venv1\Lib\site-packages\django\db\models\base.py", line 998, in save_base
    updated = self._save_table(
              ^^^^^^^^^^^^^^^^^
  File "C:\Users\Maryo\virtualEnv\venv1\Lib\site-packages\django\db\models\base.py", line 1161, in _save_table
    results = self._do_insert(
              ^^^^^^^^^^^^^^^^
  File "C:\Users\Maryo\virtualEnv\venv1\Lib\site-packages\django\db\models\base.py", line 1202, in _do_insert
    return manager._insert(
           ^^^^^^^^^^^^^^^^
  File "C:\Users\Maryo\virtualEnv\venv1\Lib\site-packages\django\db\models\manager.py", line 87, in manager_method
    return getattr(self.get_queryset(), name)(*args, **kwargs)
           ^^^^^^^^^^^^^^^^^^^^^^^^^^^^^^^^^^^^^^^^^^^^^^^^^^^
  File "C:\Users\Maryo\virtualEnv\venv1\Lib\site-packages\django\db\models\query.py", line 1847, in _insert
    return query.get_compiler(using=using).execute_sql(returning_fields)
           ^^^^^^^^^^^^^^^^^^^^^^^^^^^^^^^^^^^^^^^^^^^^^^^^^^^^^^^^^^^^^
  File "C:\Users\Maryo\virtualEnv\venv1\Lib\site-packages\django\db\models\sql\compiler.py", line 1836, in execute_sql
    cursor.execute(sql, params)
  File "C:\Users\Maryo\virtualEnv\venv1\Lib\site-packages\django\db\backends\utils.py", line 122, in execute
    return super().execute(sql, params)
           ^^^^^^^^^^^^^^^^^^^^^^^^^^^^
  File "C:\Users\Maryo\virtualEnv\venv1\Lib\site-packages\django\db\backends\utils.py", line 79, in execute
    return self._execute_with_wrappers(
           ^^^^^^^^^^^^^^^^^^^^^^^^^^^^
  File "C:\Users\Maryo\virtualEnv\venv1\Lib\site-packages\django\db\backends\utils.py", line 92, in _execute_with_wrappers
    return executor(sql, params, many, context)
           ^^^^^^^^^^^^^^^^^^^^^^^^^^^^^^^^^^^^
  File "C:\Users\Maryo\virtualEnv\venv1\Lib\site-packages\django\db\backends\utils.py", line 100, in _execute
    with self.db.wrap_database_errors:
  File "C:\Users\Maryo\virtualEnv\venv1\Lib\site-packages\django\db\utils.py", line 91, in __exit__
    raise dj_exc_value.with_traceback(traceback) from exc_value
  File "C:\Users\Maryo\virtualEnv\venv1\Lib\site-packages\django\db\backends\utils.py", line 105, in _execute
    return self.cursor.execute(sql, params)
           ^^^^^^^^^^^^^^^^^^^^^^^^^^^^^^^^
django.db.utils.IntegrityError: duplicate key value violates unique constraint "custom_user_username_key"
DETAIL:  Key (username)=(maryo100) already exists.

[ERROR] 2025-02-20 08:48:22,306 basehttp - "POST /aplicatie_exemplu/register/ HTTP/1.1" 500 157293
[ERROR] 2025-02-20 08:48:22,378 log - Internal Server Error: /aplicatie_exemplu/register/
Traceback (most recent call last):
  File "C:\Users\Maryo\virtualEnv\venv1\Lib\site-packages\django\db\backends\utils.py", line 105, in _execute
    return self.cursor.execute(sql, params)
           ^^^^^^^^^^^^^^^^^^^^^^^^^^^^^^^^
psycopg2.errors.UniqueViolation: duplicate key value violates unique constraint "custom_user_username_key"
DETAIL:  Key (username)=(maryo100) already exists.


The above exception was the direct cause of the following exception:

Traceback (most recent call last):
  File "C:\Users\Maryo\virtualEnv\venv1\Lib\site-packages\django\core\handlers\exception.py", line 55, in inner
    response = get_response(request)
               ^^^^^^^^^^^^^^^^^^^^^
  File "C:\Users\Maryo\virtualEnv\venv1\Lib\site-packages\django\core\handlers\base.py", line 197, in _get_response
    response = wrapped_callback(request, *callback_args, **callback_kwargs)
               ^^^^^^^^^^^^^^^^^^^^^^^^^^^^^^^^^^^^^^^^^^^^^^^^^^^^^^^^^^^^
  File "C:\Users\Maryo\proiectDjangolaBune\aplicatie_exemplu\views.py", line 157, in register
    user.save()
  File "C:\Users\Maryo\virtualEnv\venv1\Lib\site-packages\django\contrib\auth\base_user.py", line 62, in save
    super().save(*args, **kwargs)
  File "C:\Users\Maryo\virtualEnv\venv1\Lib\site-packages\django\db\models\base.py", line 892, in save
    self.save_base(
  File "C:\Users\Maryo\virtualEnv\venv1\Lib\site-packages\django\db\models\base.py", line 998, in save_base
    updated = self._save_table(
              ^^^^^^^^^^^^^^^^^
  File "C:\Users\Maryo\virtualEnv\venv1\Lib\site-packages\django\db\models\base.py", line 1161, in _save_table
    results = self._do_insert(
              ^^^^^^^^^^^^^^^^
  File "C:\Users\Maryo\virtualEnv\venv1\Lib\site-packages\django\db\models\base.py", line 1202, in _do_insert
    return manager._insert(
           ^^^^^^^^^^^^^^^^
  File "C:\Users\Maryo\virtualEnv\venv1\Lib\site-packages\django\db\models\manager.py", line 87, in manager_method
    return getattr(self.get_queryset(), name)(*args, **kwargs)
           ^^^^^^^^^^^^^^^^^^^^^^^^^^^^^^^^^^^^^^^^^^^^^^^^^^^
  File "C:\Users\Maryo\virtualEnv\venv1\Lib\site-packages\django\db\models\query.py", line 1847, in _insert
    return query.get_compiler(using=using).execute_sql(returning_fields)
           ^^^^^^^^^^^^^^^^^^^^^^^^^^^^^^^^^^^^^^^^^^^^^^^^^^^^^^^^^^^^^
  File "C:\Users\Maryo\virtualEnv\venv1\Lib\site-packages\django\db\models\sql\compiler.py", line 1836, in execute_sql
    cursor.execute(sql, params)
  File "C:\Users\Maryo\virtualEnv\venv1\Lib\site-packages\django\db\backends\utils.py", line 122, in execute
    return super().execute(sql, params)
           ^^^^^^^^^^^^^^^^^^^^^^^^^^^^
  File "C:\Users\Maryo\virtualEnv\venv1\Lib\site-packages\django\db\backends\utils.py", line 79, in execute
    return self._execute_with_wrappers(
           ^^^^^^^^^^^^^^^^^^^^^^^^^^^^
  File "C:\Users\Maryo\virtualEnv\venv1\Lib\site-packages\django\db\backends\utils.py", line 92, in _execute_with_wrappers
    return executor(sql, params, many, context)
           ^^^^^^^^^^^^^^^^^^^^^^^^^^^^^^^^^^^^
  File "C:\Users\Maryo\virtualEnv\venv1\Lib\site-packages\django\db\backends\utils.py", line 100, in _execute
    with self.db.wrap_database_errors:
  File "C:\Users\Maryo\virtualEnv\venv1\Lib\site-packages\django\db\utils.py", line 91, in __exit__
    raise dj_exc_value.with_traceback(traceback) from exc_value
  File "C:\Users\Maryo\virtualEnv\venv1\Lib\site-packages\django\db\backends\utils.py", line 105, in _execute
    return self.cursor.execute(sql, params)
           ^^^^^^^^^^^^^^^^^^^^^^^^^^^^^^^^
django.db.utils.IntegrityError: duplicate key value violates unique constraint "custom_user_username_key"
DETAIL:  Key (username)=(maryo100) already exists.

[ERROR] 2025-02-20 08:48:22,381 basehttp - "POST /aplicatie_exemplu/register/ HTTP/1.1" 500 157285
[ERROR] 2025-02-20 08:48:32,653 log - Internal Server Error: /aplicatie_exemplu/register/
Traceback (most recent call last):
  File "C:\Users\Maryo\virtualEnv\venv1\Lib\site-packages\django\db\backends\utils.py", line 105, in _execute
    return self.cursor.execute(sql, params)
           ^^^^^^^^^^^^^^^^^^^^^^^^^^^^^^^^
psycopg2.errors.UniqueViolation: duplicate key value violates unique constraint "custom_user_phone_number_key"
DETAIL:  Key (phone_number)=(0732156522) already exists.


The above exception was the direct cause of the following exception:

Traceback (most recent call last):
  File "C:\Users\Maryo\virtualEnv\venv1\Lib\site-packages\django\core\handlers\exception.py", line 55, in inner
    response = get_response(request)
               ^^^^^^^^^^^^^^^^^^^^^
  File "C:\Users\Maryo\virtualEnv\venv1\Lib\site-packages\django\core\handlers\base.py", line 197, in _get_response
    response = wrapped_callback(request, *callback_args, **callback_kwargs)
               ^^^^^^^^^^^^^^^^^^^^^^^^^^^^^^^^^^^^^^^^^^^^^^^^^^^^^^^^^^^^
  File "C:\Users\Maryo\proiectDjangolaBune\aplicatie_exemplu\views.py", line 157, in register
    user.save()
  File "C:\Users\Maryo\virtualEnv\venv1\Lib\site-packages\django\contrib\auth\base_user.py", line 62, in save
    super().save(*args, **kwargs)
  File "C:\Users\Maryo\virtualEnv\venv1\Lib\site-packages\django\db\models\base.py", line 892, in save
    self.save_base(
  File "C:\Users\Maryo\virtualEnv\venv1\Lib\site-packages\django\db\models\base.py", line 998, in save_base
    updated = self._save_table(
              ^^^^^^^^^^^^^^^^^
  File "C:\Users\Maryo\virtualEnv\venv1\Lib\site-packages\django\db\models\base.py", line 1161, in _save_table
    results = self._do_insert(
              ^^^^^^^^^^^^^^^^
  File "C:\Users\Maryo\virtualEnv\venv1\Lib\site-packages\django\db\models\base.py", line 1202, in _do_insert
    return manager._insert(
           ^^^^^^^^^^^^^^^^
  File "C:\Users\Maryo\virtualEnv\venv1\Lib\site-packages\django\db\models\manager.py", line 87, in manager_method
    return getattr(self.get_queryset(), name)(*args, **kwargs)
           ^^^^^^^^^^^^^^^^^^^^^^^^^^^^^^^^^^^^^^^^^^^^^^^^^^^
  File "C:\Users\Maryo\virtualEnv\venv1\Lib\site-packages\django\db\models\query.py", line 1847, in _insert
    return query.get_compiler(using=using).execute_sql(returning_fields)
           ^^^^^^^^^^^^^^^^^^^^^^^^^^^^^^^^^^^^^^^^^^^^^^^^^^^^^^^^^^^^^
  File "C:\Users\Maryo\virtualEnv\venv1\Lib\site-packages\django\db\models\sql\compiler.py", line 1836, in execute_sql
    cursor.execute(sql, params)
  File "C:\Users\Maryo\virtualEnv\venv1\Lib\site-packages\django\db\backends\utils.py", line 122, in execute
    return super().execute(sql, params)
           ^^^^^^^^^^^^^^^^^^^^^^^^^^^^
  File "C:\Users\Maryo\virtualEnv\venv1\Lib\site-packages\django\db\backends\utils.py", line 79, in execute
    return self._execute_with_wrappers(
           ^^^^^^^^^^^^^^^^^^^^^^^^^^^^
  File "C:\Users\Maryo\virtualEnv\venv1\Lib\site-packages\django\db\backends\utils.py", line 92, in _execute_with_wrappers
    return executor(sql, params, many, context)
           ^^^^^^^^^^^^^^^^^^^^^^^^^^^^^^^^^^^^
  File "C:\Users\Maryo\virtualEnv\venv1\Lib\site-packages\django\db\backends\utils.py", line 100, in _execute
    with self.db.wrap_database_errors:
  File "C:\Users\Maryo\virtualEnv\venv1\Lib\site-packages\django\db\utils.py", line 91, in __exit__
    raise dj_exc_value.with_traceback(traceback) from exc_value
  File "C:\Users\Maryo\virtualEnv\venv1\Lib\site-packages\django\db\backends\utils.py", line 105, in _execute
    return self.cursor.execute(sql, params)
           ^^^^^^^^^^^^^^^^^^^^^^^^^^^^^^^^
django.db.utils.IntegrityError: duplicate key value violates unique constraint "custom_user_phone_number_key"
DETAIL:  Key (phone_number)=(0732156522) already exists.

[ERROR] 2025-02-20 08:48:32,663 basehttp - "POST /aplicatie_exemplu/register/ HTTP/1.1" 500 157318
[ERROR] 2025-02-20 08:48:32,726 log - Internal Server Error: /aplicatie_exemplu/register/
Traceback (most recent call last):
  File "C:\Users\Maryo\virtualEnv\venv1\Lib\site-packages\django\db\backends\utils.py", line 105, in _execute
    return self.cursor.execute(sql, params)
           ^^^^^^^^^^^^^^^^^^^^^^^^^^^^^^^^
psycopg2.errors.UniqueViolation: duplicate key value violates unique constraint "custom_user_phone_number_key"
DETAIL:  Key (phone_number)=(0732156522) already exists.


The above exception was the direct cause of the following exception:

Traceback (most recent call last):
  File "C:\Users\Maryo\virtualEnv\venv1\Lib\site-packages\django\core\handlers\exception.py", line 55, in inner
    response = get_response(request)
               ^^^^^^^^^^^^^^^^^^^^^
  File "C:\Users\Maryo\virtualEnv\venv1\Lib\site-packages\django\core\handlers\base.py", line 197, in _get_response
    response = wrapped_callback(request, *callback_args, **callback_kwargs)
               ^^^^^^^^^^^^^^^^^^^^^^^^^^^^^^^^^^^^^^^^^^^^^^^^^^^^^^^^^^^^
  File "C:\Users\Maryo\proiectDjangolaBune\aplicatie_exemplu\views.py", line 157, in register
    user.save()
  File "C:\Users\Maryo\virtualEnv\venv1\Lib\site-packages\django\contrib\auth\base_user.py", line 62, in save
    super().save(*args, **kwargs)
  File "C:\Users\Maryo\virtualEnv\venv1\Lib\site-packages\django\db\models\base.py", line 892, in save
    self.save_base(
  File "C:\Users\Maryo\virtualEnv\venv1\Lib\site-packages\django\db\models\base.py", line 998, in save_base
    updated = self._save_table(
              ^^^^^^^^^^^^^^^^^
  File "C:\Users\Maryo\virtualEnv\venv1\Lib\site-packages\django\db\models\base.py", line 1161, in _save_table
    results = self._do_insert(
              ^^^^^^^^^^^^^^^^
  File "C:\Users\Maryo\virtualEnv\venv1\Lib\site-packages\django\db\models\base.py", line 1202, in _do_insert
    return manager._insert(
           ^^^^^^^^^^^^^^^^
  File "C:\Users\Maryo\virtualEnv\venv1\Lib\site-packages\django\db\models\manager.py", line 87, in manager_method
    return getattr(self.get_queryset(), name)(*args, **kwargs)
           ^^^^^^^^^^^^^^^^^^^^^^^^^^^^^^^^^^^^^^^^^^^^^^^^^^^
  File "C:\Users\Maryo\virtualEnv\venv1\Lib\site-packages\django\db\models\query.py", line 1847, in _insert
    return query.get_compiler(using=using).execute_sql(returning_fields)
           ^^^^^^^^^^^^^^^^^^^^^^^^^^^^^^^^^^^^^^^^^^^^^^^^^^^^^^^^^^^^^
  File "C:\Users\Maryo\virtualEnv\venv1\Lib\site-packages\django\db\models\sql\compiler.py", line 1836, in execute_sql
    cursor.execute(sql, params)
  File "C:\Users\Maryo\virtualEnv\venv1\Lib\site-packages\django\db\backends\utils.py", line 122, in execute
    return super().execute(sql, params)
           ^^^^^^^^^^^^^^^^^^^^^^^^^^^^
  File "C:\Users\Maryo\virtualEnv\venv1\Lib\site-packages\django\db\backends\utils.py", line 79, in execute
    return self._execute_with_wrappers(
           ^^^^^^^^^^^^^^^^^^^^^^^^^^^^
  File "C:\Users\Maryo\virtualEnv\venv1\Lib\site-packages\django\db\backends\utils.py", line 92, in _execute_with_wrappers
    return executor(sql, params, many, context)
           ^^^^^^^^^^^^^^^^^^^^^^^^^^^^^^^^^^^^
  File "C:\Users\Maryo\virtualEnv\venv1\Lib\site-packages\django\db\backends\utils.py", line 100, in _execute
    with self.db.wrap_database_errors:
  File "C:\Users\Maryo\virtualEnv\venv1\Lib\site-packages\django\db\utils.py", line 91, in __exit__
    raise dj_exc_value.with_traceback(traceback) from exc_value
  File "C:\Users\Maryo\virtualEnv\venv1\Lib\site-packages\django\db\backends\utils.py", line 105, in _execute
    return self.cursor.execute(sql, params)
           ^^^^^^^^^^^^^^^^^^^^^^^^^^^^^^^^
django.db.utils.IntegrityError: duplicate key value violates unique constraint "custom_user_phone_number_key"
DETAIL:  Key (phone_number)=(0732156522) already exists.

[ERROR] 2025-02-20 08:48:32,729 basehttp - "POST /aplicatie_exemplu/register/ HTTP/1.1" 500 157328
[ERROR] 2025-02-20 08:48:32,878 log - Internal Server Error: /aplicatie_exemplu/register/
Traceback (most recent call last):
  File "C:\Users\Maryo\virtualEnv\venv1\Lib\site-packages\django\db\backends\utils.py", line 105, in _execute
    return self.cursor.execute(sql, params)
           ^^^^^^^^^^^^^^^^^^^^^^^^^^^^^^^^
psycopg2.errors.UniqueViolation: duplicate key value violates unique constraint "custom_user_phone_number_key"
DETAIL:  Key (phone_number)=(0732156522) already exists.


The above exception was the direct cause of the following exception:

Traceback (most recent call last):
  File "C:\Users\Maryo\virtualEnv\venv1\Lib\site-packages\django\core\handlers\exception.py", line 55, in inner
    response = get_response(request)
               ^^^^^^^^^^^^^^^^^^^^^
  File "C:\Users\Maryo\virtualEnv\venv1\Lib\site-packages\django\core\handlers\base.py", line 197, in _get_response
    response = wrapped_callback(request, *callback_args, **callback_kwargs)
               ^^^^^^^^^^^^^^^^^^^^^^^^^^^^^^^^^^^^^^^^^^^^^^^^^^^^^^^^^^^^
  File "C:\Users\Maryo\proiectDjangolaBune\aplicatie_exemplu\views.py", line 157, in register
    user.save()
  File "C:\Users\Maryo\virtualEnv\venv1\Lib\site-packages\django\contrib\auth\base_user.py", line 62, in save
    super().save(*args, **kwargs)
  File "C:\Users\Maryo\virtualEnv\venv1\Lib\site-packages\django\db\models\base.py", line 892, in save
    self.save_base(
  File "C:\Users\Maryo\virtualEnv\venv1\Lib\site-packages\django\db\models\base.py", line 998, in save_base
    updated = self._save_table(
              ^^^^^^^^^^^^^^^^^
  File "C:\Users\Maryo\virtualEnv\venv1\Lib\site-packages\django\db\models\base.py", line 1161, in _save_table
    results = self._do_insert(
              ^^^^^^^^^^^^^^^^
  File "C:\Users\Maryo\virtualEnv\venv1\Lib\site-packages\django\db\models\base.py", line 1202, in _do_insert
    return manager._insert(
           ^^^^^^^^^^^^^^^^
  File "C:\Users\Maryo\virtualEnv\venv1\Lib\site-packages\django\db\models\manager.py", line 87, in manager_method
    return getattr(self.get_queryset(), name)(*args, **kwargs)
           ^^^^^^^^^^^^^^^^^^^^^^^^^^^^^^^^^^^^^^^^^^^^^^^^^^^
  File "C:\Users\Maryo\virtualEnv\venv1\Lib\site-packages\django\db\models\query.py", line 1847, in _insert
    return query.get_compiler(using=using).execute_sql(returning_fields)
           ^^^^^^^^^^^^^^^^^^^^^^^^^^^^^^^^^^^^^^^^^^^^^^^^^^^^^^^^^^^^^
  File "C:\Users\Maryo\virtualEnv\venv1\Lib\site-packages\django\db\models\sql\compiler.py", line 1836, in execute_sql
    cursor.execute(sql, params)
  File "C:\Users\Maryo\virtualEnv\venv1\Lib\site-packages\django\db\backends\utils.py", line 122, in execute
    return super().execute(sql, params)
           ^^^^^^^^^^^^^^^^^^^^^^^^^^^^
  File "C:\Users\Maryo\virtualEnv\venv1\Lib\site-packages\django\db\backends\utils.py", line 79, in execute
    return self._execute_with_wrappers(
           ^^^^^^^^^^^^^^^^^^^^^^^^^^^^
  File "C:\Users\Maryo\virtualEnv\venv1\Lib\site-packages\django\db\backends\utils.py", line 92, in _execute_with_wrappers
    return executor(sql, params, many, context)
           ^^^^^^^^^^^^^^^^^^^^^^^^^^^^^^^^^^^^
  File "C:\Users\Maryo\virtualEnv\venv1\Lib\site-packages\django\db\backends\utils.py", line 100, in _execute
    with self.db.wrap_database_errors:
  File "C:\Users\Maryo\virtualEnv\venv1\Lib\site-packages\django\db\utils.py", line 91, in __exit__
    raise dj_exc_value.with_traceback(traceback) from exc_value
  File "C:\Users\Maryo\virtualEnv\venv1\Lib\site-packages\django\db\backends\utils.py", line 105, in _execute
    return self.cursor.execute(sql, params)
           ^^^^^^^^^^^^^^^^^^^^^^^^^^^^^^^^
django.db.utils.IntegrityError: duplicate key value violates unique constraint "custom_user_phone_number_key"
DETAIL:  Key (phone_number)=(0732156522) already exists.

[ERROR] 2025-02-20 08:48:32,880 basehttp - "POST /aplicatie_exemplu/register/ HTTP/1.1" 500 157352
[ERROR] 2025-02-20 08:49:58,631 log - Internal Server Error: /aplicatie_exemplu/register/
Traceback (most recent call last):
  File "C:\Users\Maryo\virtualEnv\venv1\Lib\site-packages\django\db\backends\utils.py", line 105, in _execute
    return self.cursor.execute(sql, params)
           ^^^^^^^^^^^^^^^^^^^^^^^^^^^^^^^^
psycopg2.errors.UniqueViolation: duplicate key value violates unique constraint "custom_user_username_key"
DETAIL:  Key (username)=(maryo092) already exists.


The above exception was the direct cause of the following exception:

Traceback (most recent call last):
  File "C:\Users\Maryo\virtualEnv\venv1\Lib\site-packages\django\core\handlers\exception.py", line 55, in inner
    response = get_response(request)
               ^^^^^^^^^^^^^^^^^^^^^
  File "C:\Users\Maryo\virtualEnv\venv1\Lib\site-packages\django\core\handlers\base.py", line 197, in _get_response
    response = wrapped_callback(request, *callback_args, **callback_kwargs)
               ^^^^^^^^^^^^^^^^^^^^^^^^^^^^^^^^^^^^^^^^^^^^^^^^^^^^^^^^^^^^
  File "C:\Users\Maryo\proiectDjangolaBune\aplicatie_exemplu\views.py", line 157, in register
    user.save()
  File "C:\Users\Maryo\virtualEnv\venv1\Lib\site-packages\django\contrib\auth\base_user.py", line 62, in save
    super().save(*args, **kwargs)
  File "C:\Users\Maryo\virtualEnv\venv1\Lib\site-packages\django\db\models\base.py", line 892, in save
    self.save_base(
  File "C:\Users\Maryo\virtualEnv\venv1\Lib\site-packages\django\db\models\base.py", line 998, in save_base
    updated = self._save_table(
              ^^^^^^^^^^^^^^^^^
  File "C:\Users\Maryo\virtualEnv\venv1\Lib\site-packages\django\db\models\base.py", line 1161, in _save_table
    results = self._do_insert(
              ^^^^^^^^^^^^^^^^
  File "C:\Users\Maryo\virtualEnv\venv1\Lib\site-packages\django\db\models\base.py", line 1202, in _do_insert
    return manager._insert(
           ^^^^^^^^^^^^^^^^
  File "C:\Users\Maryo\virtualEnv\venv1\Lib\site-packages\django\db\models\manager.py", line 87, in manager_method
    return getattr(self.get_queryset(), name)(*args, **kwargs)
           ^^^^^^^^^^^^^^^^^^^^^^^^^^^^^^^^^^^^^^^^^^^^^^^^^^^
  File "C:\Users\Maryo\virtualEnv\venv1\Lib\site-packages\django\db\models\query.py", line 1847, in _insert
    return query.get_compiler(using=using).execute_sql(returning_fields)
           ^^^^^^^^^^^^^^^^^^^^^^^^^^^^^^^^^^^^^^^^^^^^^^^^^^^^^^^^^^^^^
  File "C:\Users\Maryo\virtualEnv\venv1\Lib\site-packages\django\db\models\sql\compiler.py", line 1836, in execute_sql
    cursor.execute(sql, params)
  File "C:\Users\Maryo\virtualEnv\venv1\Lib\site-packages\django\db\backends\utils.py", line 122, in execute
    return super().execute(sql, params)
           ^^^^^^^^^^^^^^^^^^^^^^^^^^^^
  File "C:\Users\Maryo\virtualEnv\venv1\Lib\site-packages\django\db\backends\utils.py", line 79, in execute
    return self._execute_with_wrappers(
           ^^^^^^^^^^^^^^^^^^^^^^^^^^^^
  File "C:\Users\Maryo\virtualEnv\venv1\Lib\site-packages\django\db\backends\utils.py", line 92, in _execute_with_wrappers
    return executor(sql, params, many, context)
           ^^^^^^^^^^^^^^^^^^^^^^^^^^^^^^^^^^^^
  File "C:\Users\Maryo\virtualEnv\venv1\Lib\site-packages\django\db\backends\utils.py", line 100, in _execute
    with self.db.wrap_database_errors:
  File "C:\Users\Maryo\virtualEnv\venv1\Lib\site-packages\django\db\utils.py", line 91, in __exit__
    raise dj_exc_value.with_traceback(traceback) from exc_value
  File "C:\Users\Maryo\virtualEnv\venv1\Lib\site-packages\django\db\backends\utils.py", line 105, in _execute
    return self.cursor.execute(sql, params)
           ^^^^^^^^^^^^^^^^^^^^^^^^^^^^^^^^
django.db.utils.IntegrityError: duplicate key value violates unique constraint "custom_user_username_key"
DETAIL:  Key (username)=(maryo092) already exists.

[ERROR] 2025-02-20 08:49:58,635 basehttp - "POST /aplicatie_exemplu/register/ HTTP/1.1" 500 157363
[ERROR] 2025-02-21 06:01:23,478 basehttp - "GET /aplicatie_exemplu/logout/ HTTP/1.1" 500 67561
[ERROR] 2025-02-21 07:25:39,122 log - Internal Server Error: /aplicatie_exemplu/sitemap
Traceback (most recent call last):
  File "C:\Users\Maryo\virtualEnv\venv1\Lib\site-packages\django\core\handlers\exception.py", line 55, in inner
    response = get_response(request)
               ^^^^^^^^^^^^^^^^^^^^^
  File "C:\Users\Maryo\virtualEnv\venv1\Lib\site-packages\django\core\handlers\base.py", line 197, in _get_response
    response = wrapped_callback(request, *callback_args, **callback_kwargs)
               ^^^^^^^^^^^^^^^^^^^^^^^^^^^^^^^^^^^^^^^^^^^^^^^^^^^^^^^^^^^^
  File "C:\Users\Maryo\virtualEnv\venv1\Lib\site-packages\django\contrib\sitemaps\views.py", line 23, in inner
    response = func(request, *args, **kwargs)
               ^^^^^^^^^^^^^^^^^^^^^^^^^^^^^^
  File "C:\Users\Maryo\virtualEnv\venv1\Lib\site-packages\django\contrib\sitemaps\views.py", line 117, in sitemap
    urls.extend(site.get_urls(page=page, site=req_site, protocol=req_protocol))
                ^^^^^^^^^^^^^^^^^^^^^^^^^^^^^^^^^^^^^^^^^^^^^^^^^^^^^^^^^^^^^^
  File "C:\Users\Maryo\virtualEnv\venv1\Lib\site-packages\django\contrib\sitemaps\__init__.py", line 104, in get_urls
    return self._urls(page, protocol, domain)
           ^^^^^^^^^^^^^^^^^^^^^^^^^^^^^^^^^^
  File "C:\Users\Maryo\virtualEnv\venv1\Lib\site-packages\django\contrib\sitemaps\__init__.py", line 124, in _urls
    loc = f"{protocol}://{domain}{self._location(item)}"
                                  ^^^^^^^^^^^^^^^^^^^^
  File "C:\Users\Maryo\virtualEnv\venv1\Lib\site-packages\django\contrib\sitemaps\__init__.py", line 69, in _location
    return self._get("location", item)
           ^^^^^^^^^^^^^^^^^^^^^^^^^^^
  File "C:\Users\Maryo\virtualEnv\venv1\Lib\site-packages\django\contrib\sitemaps\__init__.py", line 39, in _get
    return attr(item)
           ^^^^^^^^^^
  File "C:\Users\Maryo\proiectDjangolaBune\aplicatie_exemplu\sitemap.py", line 24, in location
    return reverse('categorie_detail', kwargs={'id': obj.id})
           ^^^^^^^^^^^^^^^^^^^^^^^^^^^^^^^^^^^^^^^^^^^^^^^^^^
  File "C:\Users\Maryo\virtualEnv\venv1\Lib\site-packages\django\urls\base.py", line 88, in reverse
    return resolver._reverse_with_prefix(view, prefix, *args, **kwargs)
           ^^^^^^^^^^^^^^^^^^^^^^^^^^^^^^^^^^^^^^^^^^^^^^^^^^^^^^^^^^^^
  File "C:\Users\Maryo\virtualEnv\venv1\Lib\site-packages\django\urls\resolvers.py", line 831, in _reverse_with_prefix
    raise NoReverseMatch(msg)
django.urls.exceptions.NoReverseMatch: Reverse for 'categorie_detail' not found. 'categorie_detail' is not a valid view function or pattern name.
[ERROR] 2025-02-21 07:25:39,123 basehttp - "GET /aplicatie_exemplu/sitemap HTTP/1.1" 500 110387
[ERROR] 2025-02-21 07:26:01,269 log - Internal Server Error: /aplicatie_exemplu/sitemap.xml
Traceback (most recent call last):
  File "C:\Users\Maryo\virtualEnv\venv1\Lib\site-packages\django\core\handlers\exception.py", line 55, in inner
    response = get_response(request)
               ^^^^^^^^^^^^^^^^^^^^^
  File "C:\Users\Maryo\virtualEnv\venv1\Lib\site-packages\django\core\handlers\base.py", line 197, in _get_response
    response = wrapped_callback(request, *callback_args, **callback_kwargs)
               ^^^^^^^^^^^^^^^^^^^^^^^^^^^^^^^^^^^^^^^^^^^^^^^^^^^^^^^^^^^^
  File "C:\Users\Maryo\virtualEnv\venv1\Lib\site-packages\django\contrib\sitemaps\views.py", line 23, in inner
    response = func(request, *args, **kwargs)
               ^^^^^^^^^^^^^^^^^^^^^^^^^^^^^^
  File "C:\Users\Maryo\virtualEnv\venv1\Lib\site-packages\django\contrib\sitemaps\views.py", line 117, in sitemap
    urls.extend(site.get_urls(page=page, site=req_site, protocol=req_protocol))
                ^^^^^^^^^^^^^^^^^^^^^^^^^^^^^^^^^^^^^^^^^^^^^^^^^^^^^^^^^^^^^^
  File "C:\Users\Maryo\virtualEnv\venv1\Lib\site-packages\django\contrib\sitemaps\__init__.py", line 104, in get_urls
    return self._urls(page, protocol, domain)
           ^^^^^^^^^^^^^^^^^^^^^^^^^^^^^^^^^^
  File "C:\Users\Maryo\virtualEnv\venv1\Lib\site-packages\django\contrib\sitemaps\__init__.py", line 124, in _urls
    loc = f"{protocol}://{domain}{self._location(item)}"
                                  ^^^^^^^^^^^^^^^^^^^^
  File "C:\Users\Maryo\virtualEnv\venv1\Lib\site-packages\django\contrib\sitemaps\__init__.py", line 69, in _location
    return self._get("location", item)
           ^^^^^^^^^^^^^^^^^^^^^^^^^^^
  File "C:\Users\Maryo\virtualEnv\venv1\Lib\site-packages\django\contrib\sitemaps\__init__.py", line 39, in _get
    return attr(item)
           ^^^^^^^^^^
  File "C:\Users\Maryo\proiectDjangolaBune\aplicatie_exemplu\sitemap.py", line 24, in location
    return reverse('categorie_detail', kwargs={'id': obj.id})
           ^^^^^^^^^^^^^^^^^^^^^^^^^^^^^^^^^^^^^^^^^^^^^^^^^^
  File "C:\Users\Maryo\virtualEnv\venv1\Lib\site-packages\django\urls\base.py", line 88, in reverse
    return resolver._reverse_with_prefix(view, prefix, *args, **kwargs)
           ^^^^^^^^^^^^^^^^^^^^^^^^^^^^^^^^^^^^^^^^^^^^^^^^^^^^^^^^^^^^
  File "C:\Users\Maryo\virtualEnv\venv1\Lib\site-packages\django\urls\resolvers.py", line 831, in _reverse_with_prefix
    raise NoReverseMatch(msg)
django.urls.exceptions.NoReverseMatch: Reverse for 'categorie_detail' not found. 'categorie_detail' is not a valid view function or pattern name.
[ERROR] 2025-02-21 07:26:01,270 basehttp - "GET /aplicatie_exemplu/sitemap.xml HTTP/1.1" 500 110431
[ERROR] 2025-02-21 07:34:29,253 log - Internal Server Error: /aplicatie_exemplu/sitemap.xml
Traceback (most recent call last):
  File "C:\Users\Maryo\virtualEnv\venv1\Lib\site-packages\django\core\handlers\exception.py", line 55, in inner
    response = get_response(request)
               ^^^^^^^^^^^^^^^^^^^^^
  File "C:\Users\Maryo\virtualEnv\venv1\Lib\site-packages\django\core\handlers\base.py", line 220, in _get_response
    response = response.render()
               ^^^^^^^^^^^^^^^^^
  File "C:\Users\Maryo\virtualEnv\venv1\Lib\site-packages\django\template\response.py", line 114, in render
    self.content = self.rendered_content
                   ^^^^^^^^^^^^^^^^^^^^^
  File "C:\Users\Maryo\virtualEnv\venv1\Lib\site-packages\django\template\response.py", line 90, in rendered_content
    template = self.resolve_template(self.template_name)
               ^^^^^^^^^^^^^^^^^^^^^^^^^^^^^^^^^^^^^^^^^
  File "C:\Users\Maryo\virtualEnv\venv1\Lib\site-packages\django\template\response.py", line 74, in resolve_template
    return get_template(template, using=self.using)
           ^^^^^^^^^^^^^^^^^^^^^^^^^^^^^^^^^^^^^^^^
  File "C:\Users\Maryo\virtualEnv\venv1\Lib\site-packages\django\template\loader.py", line 19, in get_template
    raise TemplateDoesNotExist(template_name, chain=chain)
django.template.exceptions.TemplateDoesNotExist: sitemap.xml
[ERROR] 2025-02-21 07:34:29,254 basehttp - "GET /aplicatie_exemplu/sitemap.xml HTTP/1.1" 500 81839
