[WARNING] 2025-02-20 04:29:57,478 log - Not Found: /accounts/login/
[WARNING] 2025-02-20 04:29:57,478 basehttp - "GET /accounts/login/?next=/aplicatie_exemplu/add-product/ HTTP/1.1" 404 2426
[WARNING] 2025-02-20 04:30:00,683 log - Not Found: /accounts/login/
[WARNING] 2025-02-20 04:30:00,683 basehttp - "GET /accounts/login/?next=/aplicatie_exemplu/add-product/ HTTP/1.1" 404 2426
[WARNING] 2025-02-20 04:30:01,282 log - Not Found: /accounts/login/
[WARNING] 2025-02-20 04:30:01,282 basehttp - "GET /accounts/login/?next=/aplicatie_exemplu/add-product/ HTTP/1.1" 404 2426
[WARNING] 2025-02-20 04:30:10,581 log - Forbidden (CSRF token from POST incorrect.): /aplicatie_exemplu/login/
[WARNING] 2025-02-20 04:30:10,581 basehttp - "POST /aplicatie_exemplu/login/ HTTP/1.1" 403 2503
[WARNING] 2025-02-20 04:30:12,299 log - Forbidden (CSRF token from POST incorrect.): /aplicatie_exemplu/login/
[WARNING] 2025-02-20 04:30:12,299 basehttp - "POST /aplicatie_exemplu/login/ HTTP/1.1" 403 2503
[WARNING] 2025-02-20 04:30:15,712 log - Forbidden (CSRF token from POST incorrect.): /aplicatie_exemplu/login/
[WARNING] 2025-02-20 04:30:15,712 basehttp - "POST /aplicatie_exemplu/login/ HTTP/1.1" 403 2503
[WARNING] 2025-02-20 04:30:17,228 log - Forbidden (CSRF token from POST incorrect.): /aplicatie_exemplu/login/
[WARNING] 2025-02-20 04:30:17,228 basehttp - "POST /aplicatie_exemplu/login/ HTTP/1.1" 403 2503
[WARNING] 2025-02-20 04:30:53,291 log - Bad Request: /aplicatie_exemplu/login/
[WARNING] 2025-02-20 04:30:53,332 log - Bad Request: /aplicatie_exemplu/login/
[WARNING] 2025-02-20 04:31:10,665 log - Bad Request: /aplicatie_exemplu/login/
[WARNING] 2025-02-20 04:31:10,665 basehttp - "POST /aplicatie_exemplu/login/ HTTP/1.1" 400 106
[WARNING] 2025-02-20 04:31:22,358 log - Not Found: /accounts/login/
[WARNING] 2025-02-20 04:31:22,358 basehttp - "GET /accounts/login/?next=/aplicatie_exemplu/add-product/ HTTP/1.1" 404 2426
[WARNING] 2025-02-20 04:31:26,165 log - Forbidden (CSRF token from POST incorrect.): /admin/login/
[WARNING] 2025-02-20 04:31:26,165 basehttp - "POST /admin/login/?next=/admin/ HTTP/1.1" 403 2503
[WARNING] 2025-02-20 04:31:29,285 log - Forbidden (CSRF token from POST incorrect.): /admin/login/
[WARNING] 2025-02-20 04:31:29,285 basehttp - "POST /admin/login/?next=/admin/ HTTP/1.1" 403 2503
[WARNING] 2025-02-20 04:31:42,326 log - Not Found: /admin/l
[WARNING] 2025-02-20 04:31:42,326 basehttp - "GET /admin/l HTTP/1.1" 404 7580
[WARNING] 2025-02-20 04:32:31,463 log - Not Found: /accounts/login/
[WARNING] 2025-02-20 04:32:31,463 basehttp - "GET /accounts/login/?next=/aplicatie_exemplu/add-product/ HTTP/1.1" 404 2426
[WARNING] 2025-02-20 04:32:44,405 log - Not Found: /accounts/login/
[WARNING] 2025-02-20 04:32:44,405 basehttp - "GET /accounts/login/?next=/aplicatie_exemplu/add-product/ HTTP/1.1" 404 2426
[WARNING] 2025-02-20 04:32:52,757 log - Not Found: /accounts/login/
[WARNING] 2025-02-20 04:32:52,757 basehttp - "GET /accounts/login/?next=/aplicatie_exemplu/add-product/ HTTP/1.1" 404 2426
[WARNING] 2025-02-20 04:32:53,686 log - Not Found: /accounts/login/
[WARNING] 2025-02-20 04:32:53,686 basehttp - "GET /accounts/login/?next=/aplicatie_exemplu/add-product/ HTTP/1.1" 404 2426
[WARNING] 2025-02-20 04:32:54,364 log - Not Found: /accounts/login/
[WARNING] 2025-02-20 04:32:54,364 basehttp - "GET /accounts/login/?next=/aplicatie_exemplu/add-product/ HTTP/1.1" 404 2426
[WARNING] 2025-02-20 04:32:54,526 log - Not Found: /accounts/login/
[WARNING] 2025-02-20 04:32:54,526 basehttp - "GET /accounts/login/?next=/aplicatie_exemplu/add-product/ HTTP/1.1" 404 2426
[WARNING] 2025-02-20 04:32:54,698 log - Not Found: /accounts/login/
[WARNING] 2025-02-20 04:32:54,698 basehttp - "GET /accounts/login/?next=/aplicatie_exemplu/add-product/ HTTP/1.1" 404 2426
[WARNING] 2025-02-20 04:32:54,836 log - Not Found: /accounts/login/
[WARNING] 2025-02-20 04:32:54,836 basehttp - "GET /accounts/login/?next=/aplicatie_exemplu/add-product/ HTTP/1.1" 404 2426
[WARNING] 2025-02-20 04:32:54,990 log - Not Found: /accounts/login/
[WARNING] 2025-02-20 04:32:54,990 basehttp - "GET /accounts/login/?next=/aplicatie_exemplu/add-product/ HTTP/1.1" 404 2426
[WARNING] 2025-02-20 04:32:56,130 log - Not Found: /accounts/login/
[WARNING] 2025-02-20 04:32:56,130 basehttp - "GET /accounts/login/?next=/aplicatie_exemplu/add-product/ HTTP/1.1" 404 2426
[WARNING] 2025-02-20 04:33:00,213 log - Not Found: /accounts/login/
[WARNING] 2025-02-20 04:33:00,213 basehttp - "GET /accounts/login/?next=/aplicatie_exemplu/add-product/ HTTP/1.1" 404 2426
[WARNING] 2025-02-20 04:33:24,740 log - Not Found: /accounts/login/
[WARNING] 2025-02-20 04:33:24,748 basehttp - "GET /accounts/login/?next=/aplicatie_exemplu/add-product/ HTTP/1.1" 404 2426
[WARNING] 2025-02-20 04:33:34,600 log - Not Found: /accounts/login/
[WARNING] 2025-02-20 04:33:34,600 basehttp - "GET /accounts/login/?next=/aplicatie_exemplu/add-product/ HTTP/1.1" 404 2426
[WARNING] 2025-02-20 04:35:20,782 log - Forbidden (CSRF token from POST incorrect.): /aplicatie_exemplu/login/
[WARNING] 2025-02-20 04:35:20,782 basehttp - "POST /aplicatie_exemplu/login/ HTTP/1.1" 403 2503
[WARNING] 2025-02-20 04:35:21,425 log - Forbidden (CSRF token from POST incorrect.): /aplicatie_exemplu/login/
[WARNING] 2025-02-20 04:35:21,433 basehttp - "POST /aplicatie_exemplu/login/ HTTP/1.1" 403 2503
[WARNING] 2025-02-20 04:35:27,218 log - Bad Request: /aplicatie_exemplu/login/
[WARNING] 2025-02-20 04:35:27,218 basehttp - "POST /aplicatie_exemplu/login/ HTTP/1.1" 400 106
[WARNING] 2025-02-20 04:40:48,642 log - Not Found: /aplicatie_exemplu/index/
[WARNING] 2025-02-20 04:40:48,642 basehttp - "GET /aplicatie_exemplu/index/ HTTP/1.1" 404 7066
[WARNING] 2025-02-20 04:42:40,819 log - Not Found: /accounts/login/
[WARNING] 2025-02-20 04:42:40,819 basehttp - "GET /accounts/login/?next=/aplicatie_exemplu/oferta/ HTTP/1.1" 404 2421
[WARNING] 2025-02-20 04:43:00,099 log - Not Found: /accounts/login/
[WARNING] 2025-02-20 04:43:00,099 basehttp - "GET /accounts/login/?next=/aplicatie_exemplu/claim_oferta/ HTTP/1.1" 404 2427
[WARNING] 2025-02-20 04:43:58,121 log - Not Found: /aplicatie_exemplu/claim_oferta/
[WARNING] 2025-02-20 04:43:58,121 basehttp - "GET /aplicatie_exemplu/claim_oferta/ HTTP/1.1" 404 7087
[WARNING] 2025-02-20 04:44:19,220 log - Not Found: /aplicatie_exemplu/claim_oferta/
[WARNING] 2025-02-20 04:44:19,220 basehttp - "GET /aplicatie_exemplu/claim_oferta/ HTTP/1.1" 404 7087
[WARNING] 2025-02-20 04:44:21,500 log - Not Found: /accounts/login/
[WARNING] 2025-02-20 04:44:21,508 basehttp - "GET /accounts/login/?next=/aplicatie_exemplu/claim_oferta/ HTTP/1.1" 404 2427
[WARNING] 2025-02-20 04:44:21,750 log - Not Found: /accounts/login/
[WARNING] 2025-02-20 04:44:21,750 basehttp - "GET /accounts/login/?next=/aplicatie_exemplu/claim_oferta/ HTTP/1.1" 404 2427
[WARNING] 2025-02-20 04:44:21,894 log - Not Found: /accounts/login/
[WARNING] 2025-02-20 04:44:21,894 basehttp - "GET /accounts/login/?next=/aplicatie_exemplu/claim_oferta/ HTTP/1.1" 404 2427
[WARNING] 2025-02-20 04:44:22,071 log - Not Found: /accounts/login/
[WARNING] 2025-02-20 04:44:22,071 basehttp - "GET /accounts/login/?next=/aplicatie_exemplu/claim_oferta/ HTTP/1.1" 404 2427
[WARNING] 2025-02-20 04:44:54,451 log - Not Found: /accounts/profile/
[WARNING] 2025-02-20 04:44:54,451 basehttp - "GET /accounts/profile/ HTTP/1.1" 404 2567
[WARNING] 2025-02-20 04:44:56,946 log - Forbidden (CSRF token from POST incorrect.): /accounts/login/
[WARNING] 2025-02-20 04:44:56,946 basehttp - "POST /accounts/login/ HTTP/1.1" 403 2503
[WARNING] 2025-02-20 04:44:58,371 log - Forbidden (CSRF token from POST incorrect.): /accounts/login/
[WARNING] 2025-02-20 04:44:58,371 basehttp - "POST /accounts/login/ HTTP/1.1" 403 2503
[WARNING] 2025-02-20 04:44:59,803 log - Forbidden (CSRF token from POST incorrect.): /accounts/login/
[WARNING] 2025-02-20 04:44:59,803 basehttp - "POST /accounts/login/ HTTP/1.1" 403 2503
[WARNING] 2025-02-20 04:45:00,076 log - Forbidden (CSRF token from POST incorrect.): /accounts/login/
[WARNING] 2025-02-20 04:45:00,076 basehttp - "POST /accounts/login/ HTTP/1.1" 403 2503
[WARNING] 2025-02-20 04:45:00,259 log - Forbidden (CSRF token from POST incorrect.): /accounts/login/
[WARNING] 2025-02-20 04:45:00,259 basehttp - "POST /accounts/login/ HTTP/1.1" 403 2503
[WARNING] 2025-02-20 04:45:00,454 log - Forbidden (CSRF token from POST incorrect.): /accounts/login/
[WARNING] 2025-02-20 04:45:00,454 basehttp - "POST /accounts/login/ HTTP/1.1" 403 2503
[WARNING] 2025-02-20 04:45:00,692 log - Forbidden (CSRF token from POST incorrect.): /accounts/login/
[WARNING] 2025-02-20 04:45:00,692 basehttp - "POST /accounts/login/ HTTP/1.1" 403 2503
[WARNING] 2025-02-20 04:45:00,917 log - Forbidden (CSRF token from POST incorrect.): /accounts/login/
[WARNING] 2025-02-20 04:45:00,917 basehttp - "POST /accounts/login/ HTTP/1.1" 403 2503
[WARNING] 2025-02-20 04:45:01,168 log - Forbidden (CSRF token from POST incorrect.): /accounts/login/
[WARNING] 2025-02-20 04:45:01,168 basehttp - "POST /accounts/login/ HTTP/1.1" 403 2503
[WARNING] 2025-02-20 04:45:01,389 log - Forbidden (CSRF token from POST incorrect.): /accounts/login/
[WARNING] 2025-02-20 04:45:01,389 basehttp - "POST /accounts/login/ HTTP/1.1" 403 2503
[WARNING] 2025-02-20 04:45:01,605 log - Forbidden (CSRF token from POST incorrect.): /accounts/login/
[WARNING] 2025-02-20 04:45:01,605 basehttp - "POST /accounts/login/ HTTP/1.1" 403 2503
[WARNING] 2025-02-20 04:45:01,772 log - Forbidden (CSRF token from POST incorrect.): /accounts/login/
[WARNING] 2025-02-20 04:45:01,772 basehttp - "POST /accounts/login/ HTTP/1.1" 403 2503
[WARNING] 2025-02-20 04:45:01,961 log - Forbidden (CSRF token from POST incorrect.): /accounts/login/
[WARNING] 2025-02-20 04:45:01,969 basehttp - "POST /accounts/login/ HTTP/1.1" 403 2503
[WARNING] 2025-02-20 04:45:02,124 log - Forbidden (CSRF token from POST incorrect.): /accounts/login/
[WARNING] 2025-02-20 04:45:02,124 basehttp - "POST /accounts/login/ HTTP/1.1" 403 2503
[WARNING] 2025-02-20 04:45:05,376 log - Forbidden (CSRF token from POST incorrect.): /accounts/login/
[WARNING] 2025-02-20 04:45:05,385 basehttp - "POST /accounts/login/ HTTP/1.1" 403 2503
[WARNING] 2025-02-20 04:45:05,973 log - Forbidden (CSRF token from POST incorrect.): /accounts/login/
[WARNING] 2025-02-20 04:45:05,973 basehttp - "POST /accounts/login/ HTTP/1.1" 403 2503
[WARNING] 2025-02-20 04:45:12,464 log - Not Found: /accounts/profile/
[WARNING] 2025-02-20 04:45:12,464 basehttp - "GET /accounts/profile/ HTTP/1.1" 404 2567
[WARNING] 2025-02-20 04:45:31,748 log - Not Found: /accounts/profile/
[WARNING] 2025-02-20 04:45:31,748 basehttp - "GET /accounts/profile/ HTTP/1.1" 404 2567
[WARNING] 2025-02-20 04:47:54,895 log - Bad Request: /aplicatie_exemplu/login/
[WARNING] 2025-02-20 04:47:54,903 basehttp - "POST /aplicatie_exemplu/login/ HTTP/1.1" 400 106
[ERROR] 2025-02-20 04:53:35,461 log - Internal Server Error: /aplicatie_exemplu/oferta/
Traceback (most recent call last):
  File "C:\Users\Maryo\virtualEnv\venv1\Lib\site-packages\django\core\handlers\exception.py", line 55, in inner
    response = get_response(request)
               ^^^^^^^^^^^^^^^^^^^^^
  File "C:\Users\Maryo\virtualEnv\venv1\Lib\site-packages\django\core\handlers\base.py", line 197, in _get_response
    response = wrapped_callback(request, *callback_args, **callback_kwargs)
               ^^^^^^^^^^^^^^^^^^^^^^^^^^^^^^^^^^^^^^^^^^^^^^^^^^^^^^^^^^^^
  File "C:\Users\Maryo\virtualEnv\venv1\Lib\site-packages\django\contrib\auth\decorators.py", line 60, in _view_wrapper
    return view_func(request, *args, **kwargs)
           ^^^^^^^^^^^^^^^^^^^^^^^^^^^^^^^^^^^
  File "C:\Users\Maryo\proiectDjangolaBune\aplicatie_exemplu\views.py", line 442, in oferta
    return render(request, "403.html", {
           ^^^^^^^^^^^^^^^^^^^^^^^^^^^^^
  File "C:\Users\Maryo\virtualEnv\venv1\Lib\site-packages\django\shortcuts.py", line 25, in render
    content = loader.render_to_string(template_name, context, request, using=using)
              ^^^^^^^^^^^^^^^^^^^^^^^^^^^^^^^^^^^^^^^^^^^^^^^^^^^^^^^^^^^^^^^^^^^^^
  File "C:\Users\Maryo\virtualEnv\venv1\Lib\site-packages\django\template\loader.py", line 62, in render_to_string
    return template.render(context, request)
           ^^^^^^^^^^^^^^^^^^^^^^^^^^^^^^^^^
  File "C:\Users\Maryo\virtualEnv\venv1\Lib\site-packages\django\template\backends\django.py", line 107, in render
    return self.template.render(context)
           ^^^^^^^^^^^^^^^^^^^^^^^^^^^^^
  File "C:\Users\Maryo\virtualEnv\venv1\Lib\site-packages\django\template\base.py", line 171, in render
    return self._render(context)
           ^^^^^^^^^^^^^^^^^^^^^
  File "C:\Users\Maryo\virtualEnv\venv1\Lib\site-packages\django\template\base.py", line 163, in _render
    return self.nodelist.render(context)
           ^^^^^^^^^^^^^^^^^^^^^^^^^^^^^
  File "C:\Users\Maryo\virtualEnv\venv1\Lib\site-packages\django\template\base.py", line 1008, in render
    return SafeString("".join([node.render_annotated(context) for node in self]))
                               ^^^^^^^^^^^^^^^^^^^^^^^^^^^^^^
  File "C:\Users\Maryo\virtualEnv\venv1\Lib\site-packages\django\template\base.py", line 969, in render_annotated
    return self.render(context)
           ^^^^^^^^^^^^^^^^^^^^
  File "C:\Users\Maryo\virtualEnv\venv1\Lib\site-packages\django\template\defaulttags.py", line 480, in render
    url = reverse(view_name, args=args, kwargs=kwargs, current_app=current_app)
          ^^^^^^^^^^^^^^^^^^^^^^^^^^^^^^^^^^^^^^^^^^^^^^^^^^^^^^^^^^^^^^^^^^^^^
  File "C:\Users\Maryo\virtualEnv\venv1\Lib\site-packages\django\urls\base.py", line 88, in reverse
    return resolver._reverse_with_prefix(view, prefix, *args, **kwargs)
           ^^^^^^^^^^^^^^^^^^^^^^^^^^^^^^^^^^^^^^^^^^^^^^^^^^^^^^^^^^^^
  File "C:\Users\Maryo\virtualEnv\venv1\Lib\site-packages\django\urls\resolvers.py", line 831, in _reverse_with_prefix
    raise NoReverseMatch(msg)
django.urls.exceptions.NoReverseMatch: Reverse for 'home' not found. 'home' is not a valid view function or pattern name.
[ERROR] 2025-02-20 04:53:35,461 basehttp - "GET /aplicatie_exemplu/oferta/ HTTP/1.1" 500 121833
[WARNING] 2025-02-20 04:54:03,532 log - Not Found: /aplicatie_exemplu/claim_oferta/
[WARNING] 2025-02-20 04:54:03,532 basehttp - "GET /aplicatie_exemplu/claim_oferta/ HTTP/1.1" 404 7087
[WARNING] 2025-02-20 04:56:19,154 log - Forbidden: /aplicatie_exemplu/oferta/
[WARNING] 2025-02-20 04:56:19,154 basehttp - "GET /aplicatie_exemplu/oferta/ HTTP/1.1" 403 1472
[WARNING] 2025-02-20 04:56:37,684 log - Forbidden (CSRF token from POST incorrect.): /admin/aplicatie_exemplu/customuser/
[WARNING] 2025-02-20 04:56:37,684 basehttp - "POST /admin/aplicatie_exemplu/customuser/ HTTP/1.1" 403 2503
[WARNING] 2025-02-20 04:57:42,885 log - Bad Request: /aplicatie_exemplu/login/
[WARNING] 2025-02-20 04:57:42,885 basehttp - "POST /aplicatie_exemplu/login/ HTTP/1.1" 400 106
[ERROR] 2025-02-20 05:15:49,444 log - Internal Server Error: /aplicatie_exemplu/
Traceback (most recent call last):
  File "C:\Users\Maryo\virtualEnv\venv1\Lib\site-packages\django\core\handlers\exception.py", line 55, in inner
    response = get_response(request)
               ^^^^^^^^^^^^^^^^^^^^^
  File "C:\Users\Maryo\virtualEnv\venv1\Lib\site-packages\django\core\handlers\base.py", line 197, in _get_response
    response = wrapped_callback(request, *callback_args, **callback_kwargs)
               ^^^^^^^^^^^^^^^^^^^^^^^^^^^^^^^^^^^^^^^^^^^^^^^^^^^^^^^^^^^^
  File "C:\Users\Maryo\proiectDjangolaBune\aplicatie_exemplu\views.py", line 455, in home
    return render(request, 'home.html')
           ^^^^^^^^^^^^^^^^^^^^^^^^^^^^
  File "C:\Users\Maryo\virtualEnv\venv1\Lib\site-packages\django\shortcuts.py", line 25, in render
    content = loader.render_to_string(template_name, context, request, using=using)
              ^^^^^^^^^^^^^^^^^^^^^^^^^^^^^^^^^^^^^^^^^^^^^^^^^^^^^^^^^^^^^^^^^^^^^
  File "C:\Users\Maryo\virtualEnv\venv1\Lib\site-packages\django\template\loader.py", line 61, in render_to_string
    template = get_template(template_name, using=using)
               ^^^^^^^^^^^^^^^^^^^^^^^^^^^^^^^^^^^^^^^^
  File "C:\Users\Maryo\virtualEnv\venv1\Lib\site-packages\django\template\loader.py", line 19, in get_template
    raise TemplateDoesNotExist(template_name, chain=chain)
django.template.exceptions.TemplateDoesNotExist: home.html
[ERROR] 2025-02-20 05:15:49,444 basehttp - "GET /aplicatie_exemplu/ HTTP/1.1" 500 80918
[WARNING] 2025-02-20 05:16:40,318 log - Not Found: /aplicatie_exemplu/index
[WARNING] 2025-02-20 05:16:40,318 basehttp - "GET /aplicatie_exemplu/index HTTP/1.1" 404 7327
[WARNING] 2025-02-20 05:21:33,934 basehttp - "GET /static/default_avatar.png HTTP/1.1" 404 1868
[WARNING] 2025-02-20 05:21:41,395 basehttp - "GET /static/default_avatar.png HTTP/1.1" 404 1868
[WARNING] 2025-02-20 05:22:34,642 basehttp - "GET /static/default_avatar.png HTTP/1.1" 404 1868
[WARNING] 2025-02-20 05:25:31,565 basehttp - "GET /static/default_avatar.png HTTP/1.1" 404 1868
[WARNING] 2025-02-20 05:26:01,358 log - Forbidden (Permission denied): /admin/aplicatie_exemplu/customuser/18/change/
Traceback (most recent call last):
  File "C:\Users\Maryo\virtualEnv\venv1\Lib\site-packages\django\core\handlers\exception.py", line 55, in inner
    response = get_response(request)
               ^^^^^^^^^^^^^^^^^^^^^
  File "C:\Users\Maryo\virtualEnv\venv1\Lib\site-packages\django\core\handlers\base.py", line 197, in _get_response
    response = wrapped_callback(request, *callback_args, **callback_kwargs)
               ^^^^^^^^^^^^^^^^^^^^^^^^^^^^^^^^^^^^^^^^^^^^^^^^^^^^^^^^^^^^
  File "C:\Users\Maryo\virtualEnv\venv1\Lib\site-packages\django\contrib\admin\options.py", line 718, in wrapper
    return self.admin_site.admin_view(view)(*args, **kwargs)
           ^^^^^^^^^^^^^^^^^^^^^^^^^^^^^^^^^^^^^^^^^^^^^^^^^
  File "C:\Users\Maryo\virtualEnv\venv1\Lib\site-packages\django\utils\decorators.py", line 188, in _view_wrapper
    result = _process_exception(request, e)
             ^^^^^^^^^^^^^^^^^^^^^^^^^^^^^^
  File "C:\Users\Maryo\virtualEnv\venv1\Lib\site-packages\django\utils\decorators.py", line 186, in _view_wrapper
    response = view_func(request, *args, **kwargs)
               ^^^^^^^^^^^^^^^^^^^^^^^^^^^^^^^^^^^
  File "C:\Users\Maryo\virtualEnv\venv1\Lib\site-packages\django\views\decorators\cache.py", line 80, in _view_wrapper
    response = view_func(request, *args, **kwargs)
               ^^^^^^^^^^^^^^^^^^^^^^^^^^^^^^^^^^^
  File "C:\Users\Maryo\virtualEnv\venv1\Lib\site-packages\django\contrib\admin\sites.py", line 241, in inner
    return view(request, *args, **kwargs)
           ^^^^^^^^^^^^^^^^^^^^^^^^^^^^^^
  File "C:\Users\Maryo\virtualEnv\venv1\Lib\site-packages\django\contrib\admin\options.py", line 1964, in change_view
    return self.changeform_view(request, object_id, form_url, extra_context)
           ^^^^^^^^^^^^^^^^^^^^^^^^^^^^^^^^^^^^^^^^^^^^^^^^^^^^^^^^^^^^^^^^^
  File "C:\Users\Maryo\virtualEnv\venv1\Lib\site-packages\django\utils\decorators.py", line 48, in _wrapper
    return bound_method(*args, **kwargs)
           ^^^^^^^^^^^^^^^^^^^^^^^^^^^^^
  File "C:\Users\Maryo\virtualEnv\venv1\Lib\site-packages\django\utils\decorators.py", line 188, in _view_wrapper
    result = _process_exception(request, e)
             ^^^^^^^^^^^^^^^^^^^^^^^^^^^^^^
  File "C:\Users\Maryo\virtualEnv\venv1\Lib\site-packages\django\utils\decorators.py", line 186, in _view_wrapper
    response = view_func(request, *args, **kwargs)
               ^^^^^^^^^^^^^^^^^^^^^^^^^^^^^^^^^^^
  File "C:\Users\Maryo\virtualEnv\venv1\Lib\site-packages\django\contrib\admin\options.py", line 1820, in changeform_view
    return self._changeform_view(request, object_id, form_url, extra_context)
           ^^^^^^^^^^^^^^^^^^^^^^^^^^^^^^^^^^^^^^^^^^^^^^^^^^^^^^^^^^^^^^^^^^
  File "C:\Users\Maryo\virtualEnv\venv1\Lib\site-packages\django\contrib\admin\options.py", line 1847, in _changeform_view
    raise PermissionDenied
django.core.exceptions.PermissionDenied
[WARNING] 2025-02-20 05:26:01,359 basehttp - "GET /admin/aplicatie_exemplu/customuser/18/change/ HTTP/1.1" 403 1475
[WARNING] 2025-02-20 05:26:32,842 basehttp - "GET /static/default_avatar.png HTTP/1.1" 404 1868
[WARNING] 2025-02-20 05:29:47,977 basehttp - "GET /static/default_avatar.png HTTP/1.1" 404 1868
[WARNING] 2025-02-20 05:29:48,473 basehttp - "GET /static/default_avatar.png HTTP/1.1" 404 1868
[WARNING] 2025-02-20 05:29:48,647 basehttp - "GET /static/default_avatar.png HTTP/1.1" 404 1868
[WARNING] 2025-02-20 05:29:48,851 basehttp - "GET /static/default_avatar.png HTTP/1.1" 404 1868
[WARNING] 2025-02-20 05:29:51,088 basehttp - "GET /static/default_avatar.png HTTP/1.1" 404 1868
[WARNING] 2025-02-20 05:29:51,343 basehttp - "GET /static/default_avatar.png HTTP/1.1" 404 1868
[WARNING] 2025-02-20 05:29:51,567 basehttp - "GET /static/default_avatar.png HTTP/1.1" 404 1868
[WARNING] 2025-02-20 05:30:18,060 log - Bad Request: /aplicatie_exemplu/login/
[WARNING] 2025-02-20 05:30:18,060 basehttp - "POST /aplicatie_exemplu/login/ HTTP/1.1" 400 106
[WARNING] 2025-02-20 05:30:19,962 log - Bad Request: /aplicatie_exemplu/login/
[WARNING] 2025-02-20 05:30:19,962 basehttp - "POST /aplicatie_exemplu/login/ HTTP/1.1" 400 106
[WARNING] 2025-02-20 05:30:22,763 basehttp - "GET /static/default_avatar.png HTTP/1.1" 404 1868
[WARNING] 2025-02-20 05:31:06,718 basehttp - "GET /static/default_avatar.png HTTP/1.1" 404 1868
[WARNING] 2025-02-20 05:31:07,597 basehttp - "GET /static/default_avatar.png HTTP/1.1" 404 1868
[WARNING] 2025-02-20 05:31:07,882 basehttp - "GET /static/default_avatar.png HTTP/1.1" 404 1868
[WARNING] 2025-02-20 05:31:14,331 basehttp - "GET /static/default_avatar.png HTTP/1.1" 404 1868
[WARNING] 2025-02-20 05:31:15,087 basehttp - "GET /static/default_avatar.png HTTP/1.1" 404 1868
[WARNING] 2025-02-20 05:31:15,450 basehttp - "GET /static/default_avatar.png HTTP/1.1" 404 1868
[WARNING] 2025-02-20 05:33:15,848 log - Not Found: /admins
[WARNING] 2025-02-20 05:33:15,848 basehttp - "GET /admins HTTP/1.1" 404 2362
[WARNING] 2025-02-20 05:33:21,255 log - Not Found: /admin/l
[WARNING] 2025-02-20 05:33:21,256 basehttp - "GET /admin/l HTTP/1.1" 404 7580
[WARNING] 2025-02-20 05:36:59,849 basehttp - "GET /static/default_avatar.png HTTP/1.1" 404 1868
[WARNING] 2025-02-20 05:41:18,089 log - Not Found: /aplicatie_exemplu/pagina_protejata/
[WARNING] 2025-02-20 05:41:18,090 basehttp - "GET /aplicatie_exemplu/pagina_protejata/ HTTP/1.1" 404 7363
[WARNING] 2025-02-20 05:41:41,066 log - Not Found: /aplicatie_exemplu/admin
[WARNING] 2025-02-20 05:41:41,067 basehttp - "GET /aplicatie_exemplu/admin HTTP/1.1" 404 7327
[WARNING] 2025-02-20 05:42:10,127 log - Not Found: /aplicatie_exemplu/pagina_protejata/
[WARNING] 2025-02-20 05:42:10,128 basehttp - "GET /aplicatie_exemplu/pagina_protejata/ HTTP/1.1" 404 7363
[WARNING] 2025-02-20 05:46:22,873 log - Not Found: /aplicatie_exemplu/lista_produse/
[WARNING] 2025-02-20 05:46:22,874 basehttp - "GET /aplicatie_exemplu/lista_produse/ HTTP/1.1" 404 7354
[WARNING] 2025-02-20 05:46:30,654 log - Not Found: /aplicatie_exemplu/lista_produse/
[WARNING] 2025-02-20 05:46:30,655 basehttp - "GET /aplicatie_exemplu/lista_produse/ HTTP/1.1" 404 7354
[WARNING] 2025-02-20 05:46:55,659 log - Not Found: /aplicatie_exemplu/lista_produse
[WARNING] 2025-02-20 05:46:55,660 basehttp - "GET /aplicatie_exemplu/lista_produse HTTP/1.1" 404 7351
[WARNING] 2025-02-20 05:47:29,357 log - Not Found: /aplicatie_exemplu/lista_promotii/
[WARNING] 2025-02-20 05:47:29,359 basehttp - "GET /aplicatie_exemplu/lista_promotii/ HTTP/1.1" 404 7357
[WARNING] 2025-02-20 06:17:42,294 log - Not Found: /aplicatie_exemplu/profil
[WARNING] 2025-02-20 06:17:42,295 basehttp - "GET /aplicatie_exemplu/profil HTTP/1.1" 404 7330
[WARNING] 2025-02-20 06:17:45,306 log - Not Found: /aplicatie_exemplu/profil
[WARNING] 2025-02-20 06:17:45,306 basehttp - "GET /aplicatie_exemplu/profil HTTP/1.1" 404 7330
[WARNING] 2025-02-20 06:17:56,794 log - Not Found: /aplicatie_exemplu/profil
[WARNING] 2025-02-20 06:17:56,794 basehttp - "GET /aplicatie_exemplu/profil HTTP/1.1" 404 7330
[WARNING] 2025-02-20 06:44:26,277 log - Bad Request: /aplicatie_exemplu/login/
[WARNING] 2025-02-20 06:44:26,277 basehttp - "POST /aplicatie_exemplu/login/ HTTP/1.1" 400 106
[WARNING] 2025-02-20 06:46:17,550 log - Not Found: /aplicatie_exemplu/filter_products/
[WARNING] 2025-02-20 06:46:17,551 basehttp - "GET /aplicatie_exemplu/filter_products/ HTTP/1.1" 404 7360
[WARNING] 2025-02-20 06:51:10,469 log - Forbidden: /aplicatie_exemplu/add-product/
[WARNING] 2025-02-20 06:51:10,470 basehttp - "GET /aplicatie_exemplu/add-product/ HTTP/1.1" 403 1470
[WARNING] 2025-02-20 06:53:38,178 log - Forbidden: /aplicatie_exemplu/add-product/
[WARNING] 2025-02-20 06:53:38,179 basehttp - "GET /aplicatie_exemplu/add-product/ HTTP/1.1" 403 1470
[WARNING] 2025-02-20 06:54:50,220 log - Not Found: /aplicatie_exemplu/lista_produse/
[WARNING] 2025-02-20 06:54:50,221 basehttp - "GET /aplicatie_exemplu/lista_produse/ HTTP/1.1" 404 7354
[WARNING] 2025-02-20 06:57:04,345 log - Not Found: /aplicatie_exemplu/lista_produse/
[WARNING] 2025-02-20 06:57:04,345 basehttp - "GET /aplicatie_exemplu/lista_produse/ HTTP/1.1" 404 7354
[WARNING] 2025-02-20 06:57:57,859 log - Forbidden: /aplicatie_exemplu/add-product/
[WARNING] 2025-02-20 06:57:57,859 basehttp - "GET /aplicatie_exemplu/add-product/ HTTP/1.1" 403 1470
[WARNING] 2025-02-20 06:58:36,974 log - Not Found: /aplicatie_exemplu/lista_promotii/
[WARNING] 2025-02-20 06:58:36,975 basehttp - "GET /aplicatie_exemplu/lista_promotii/ HTTP/1.1" 404 7357
[WARNING] 2025-02-20 06:58:43,753 log - Not Found: /aplicatie_exemplu/lista_promotii/
[WARNING] 2025-02-20 06:58:43,753 basehttp - "GET /aplicatie_exemplu/lista_promotii/ HTTP/1.1" 404 7357
[WARNING] 2025-02-20 06:59:04,226 log - Not Found: /aplicatie_exemplu/lista_promotii/
[WARNING] 2025-02-20 06:59:04,227 basehttp - "GET /aplicatie_exemplu/lista_promotii/ HTTP/1.1" 404 7357
[WARNING] 2025-02-20 06:59:06,033 log - Not Found: /aplicatie_exemplu/lista_promotii/
[WARNING] 2025-02-20 06:59:06,033 basehttp - "GET /aplicatie_exemplu/lista_promotii/ HTTP/1.1" 404 7357
[WARNING] 2025-02-20 06:59:06,216 log - Not Found: /aplicatie_exemplu/lista_promotii/
[WARNING] 2025-02-20 06:59:06,217 basehttp - "GET /aplicatie_exemplu/lista_promotii/ HTTP/1.1" 404 7357
[WARNING] 2025-02-20 06:59:48,839 log - Not Found: /aplicatie_exemplu/lista_produse/
[WARNING] 2025-02-20 06:59:48,840 basehttp - "GET /aplicatie_exemplu/lista_produse/ HTTP/1.1" 404 7354
[ERROR] 2025-02-20 07:55:34,526 log - Internal Server Error: /aplicatie_exemplu/contact/
Traceback (most recent call last):
  File "C:\Users\Maryo\virtualEnv\venv1\Lib\site-packages\django\core\handlers\exception.py", line 55, in inner
    response = get_response(request)
               ^^^^^^^^^^^^^^^^^^^^^
  File "C:\Users\Maryo\virtualEnv\venv1\Lib\site-packages\django\core\handlers\base.py", line 197, in _get_response
    response = wrapped_callback(request, *callback_args, **callback_kwargs)
               ^^^^^^^^^^^^^^^^^^^^^^^^^^^^^^^^^^^^^^^^^^^^^^^^^^^^^^^^^^^^
  File "C:\Users\Maryo\proiectDjangolaBune\aplicatie_exemplu\views.py", line 84, in contact_view
    return render(request, 'contact_success.html')  # Pagina de succes
           ^^^^^^^^^^^^^^^^^^^^^^^^^^^^^^^^^^^^^^^
  File "C:\Users\Maryo\virtualEnv\venv1\Lib\site-packages\django\shortcuts.py", line 25, in render
    content = loader.render_to_string(template_name, context, request, using=using)
              ^^^^^^^^^^^^^^^^^^^^^^^^^^^^^^^^^^^^^^^^^^^^^^^^^^^^^^^^^^^^^^^^^^^^^
  File "C:\Users\Maryo\virtualEnv\venv1\Lib\site-packages\django\template\loader.py", line 61, in render_to_string
    template = get_template(template_name, using=using)
               ^^^^^^^^^^^^^^^^^^^^^^^^^^^^^^^^^^^^^^^^
  File "C:\Users\Maryo\virtualEnv\venv1\Lib\site-packages\django\template\loader.py", line 19, in get_template
    raise TemplateDoesNotExist(template_name, chain=chain)
django.template.exceptions.TemplateDoesNotExist: contact_success.html
[ERROR] 2025-02-20 07:55:34,526 basehttp - "POST /aplicatie_exemplu/contact/ HTTP/1.1" 500 84780
[ERROR] 2025-02-20 08:05:00,190 log - Internal Server Error: /aplicatie_exemplu/contact/
Traceback (most recent call last):
  File "C:\Users\Maryo\virtualEnv\venv1\Lib\site-packages\django\core\handlers\exception.py", line 55, in inner
    response = get_response(request)
               ^^^^^^^^^^^^^^^^^^^^^
  File "C:\Users\Maryo\virtualEnv\venv1\Lib\site-packages\django\core\handlers\base.py", line 197, in _get_response
    response = wrapped_callback(request, *callback_args, **callback_kwargs)
               ^^^^^^^^^^^^^^^^^^^^^^^^^^^^^^^^^^^^^^^^^^^^^^^^^^^^^^^^^^^^
  File "C:\Users\Maryo\proiectDjangolaBune\aplicatie_exemplu\views.py", line 84, in contact_view
    return render(request, 'contact_success.html')  # Pagina de succes
           ^^^^^^^^^^^^^^^^^^^^^^^^^^^^^^^^^^^^^^^
  File "C:\Users\Maryo\virtualEnv\venv1\Lib\site-packages\django\shortcuts.py", line 25, in render
    content = loader.render_to_string(template_name, context, request, using=using)
              ^^^^^^^^^^^^^^^^^^^^^^^^^^^^^^^^^^^^^^^^^^^^^^^^^^^^^^^^^^^^^^^^^^^^^
  File "C:\Users\Maryo\virtualEnv\venv1\Lib\site-packages\django\template\loader.py", line 61, in render_to_string
    template = get_template(template_name, using=using)
               ^^^^^^^^^^^^^^^^^^^^^^^^^^^^^^^^^^^^^^^^
  File "C:\Users\Maryo\virtualEnv\venv1\Lib\site-packages\django\template\loader.py", line 19, in get_template
    raise TemplateDoesNotExist(template_name, chain=chain)
django.template.exceptions.TemplateDoesNotExist: contact_success.html
[ERROR] 2025-02-20 08:05:00,190 basehttp - "POST /aplicatie_exemplu/contact/ HTTP/1.1" 500 84794
[WARNING] 2025-02-20 08:07:01,653 log - Forbidden: /aplicatie_exemplu/add-product/
[WARNING] 2025-02-20 08:07:01,653 basehttp - "GET /aplicatie_exemplu/add-product/ HTTP/1.1" 403 1470
[WARNING] 2025-02-20 08:12:18,469 log - Forbidden: /aplicatie_exemplu/add-product/
[WARNING] 2025-02-20 08:12:18,469 basehttp - "GET /aplicatie_exemplu/add-product/ HTTP/1.1" 403 1470
[WARNING] 2025-02-20 08:12:26,378 log - Forbidden: /aplicatie_exemplu/add-product/
[WARNING] 2025-02-20 08:12:26,386 basehttp - "GET /aplicatie_exemplu/add-product/ HTTP/1.1" 403 1470
[WARNING] 2025-02-20 08:12:59,170 log - Not Found: /
[WARNING] 2025-02-20 08:12:59,170 basehttp - "GET / HTTP/1.1" 404 2326
[WARNING] 2025-02-20 08:13:04,463 log - Forbidden (Permission denied): /admin/aplicatie_exemplu/customuser/
Traceback (most recent call last):
  File "C:\Users\Maryo\virtualEnv\venv1\Lib\site-packages\django\core\handlers\exception.py", line 55, in inner
    response = get_response(request)
               ^^^^^^^^^^^^^^^^^^^^^
  File "C:\Users\Maryo\virtualEnv\venv1\Lib\site-packages\django\core\handlers\base.py", line 197, in _get_response
    response = wrapped_callback(request, *callback_args, **callback_kwargs)
               ^^^^^^^^^^^^^^^^^^^^^^^^^^^^^^^^^^^^^^^^^^^^^^^^^^^^^^^^^^^^
  File "C:\Users\Maryo\virtualEnv\venv1\Lib\site-packages\django\contrib\admin\options.py", line 718, in wrapper
    return self.admin_site.admin_view(view)(*args, **kwargs)
           ^^^^^^^^^^^^^^^^^^^^^^^^^^^^^^^^^^^^^^^^^^^^^^^^^
  File "C:\Users\Maryo\virtualEnv\venv1\Lib\site-packages\django\utils\decorators.py", line 188, in _view_wrapper
    result = _process_exception(request, e)
             ^^^^^^^^^^^^^^^^^^^^^^^^^^^^^^
  File "C:\Users\Maryo\virtualEnv\venv1\Lib\site-packages\django\utils\decorators.py", line 186, in _view_wrapper
    response = view_func(request, *args, **kwargs)
               ^^^^^^^^^^^^^^^^^^^^^^^^^^^^^^^^^^^
  File "C:\Users\Maryo\virtualEnv\venv1\Lib\site-packages\django\views\decorators\cache.py", line 80, in _view_wrapper
    response = view_func(request, *args, **kwargs)
               ^^^^^^^^^^^^^^^^^^^^^^^^^^^^^^^^^^^
  File "C:\Users\Maryo\virtualEnv\venv1\Lib\site-packages\django\contrib\admin\sites.py", line 241, in inner
    return view(request, *args, **kwargs)
           ^^^^^^^^^^^^^^^^^^^^^^^^^^^^^^
  File "C:\Users\Maryo\virtualEnv\venv1\Lib\site-packages\django\utils\decorators.py", line 48, in _wrapper
    return bound_method(*args, **kwargs)
           ^^^^^^^^^^^^^^^^^^^^^^^^^^^^^
  File "C:\Users\Maryo\virtualEnv\venv1\Lib\site-packages\django\utils\decorators.py", line 188, in _view_wrapper
    result = _process_exception(request, e)
             ^^^^^^^^^^^^^^^^^^^^^^^^^^^^^^
  File "C:\Users\Maryo\virtualEnv\venv1\Lib\site-packages\django\utils\decorators.py", line 186, in _view_wrapper
    response = view_func(request, *args, **kwargs)
               ^^^^^^^^^^^^^^^^^^^^^^^^^^^^^^^^^^^
  File "C:\Users\Maryo\virtualEnv\venv1\Lib\site-packages\django\contrib\admin\options.py", line 1998, in changelist_view
    raise PermissionDenied
django.core.exceptions.PermissionDenied
[WARNING] 2025-02-20 08:13:04,471 basehttp - "GET /admin/aplicatie_exemplu/customuser/ HTTP/1.1" 403 1475
[WARNING] 2025-02-20 08:13:08,927 log - Forbidden: /aplicatie_exemplu/add-product/
[WARNING] 2025-02-20 08:13:08,927 basehttp - "GET /aplicatie_exemplu/add-product/ HTTP/1.1" 403 1470
[WARNING] 2025-02-20 08:13:28,034 log - Forbidden: /aplicatie_exemplu/add-product/
[WARNING] 2025-02-20 08:13:29,162 log - Forbidden: /aplicatie_exemplu/add-product/
[WARNING] 2025-02-20 08:13:30,477 log - Forbidden: /aplicatie_exemplu/add-product/
[WARNING] 2025-02-20 08:13:36,860 log - Forbidden: /aplicatie_exemplu/add-product/
[WARNING] 2025-02-20 08:14:03,205 log - Forbidden: /aplicatie_exemplu/add-product/
[WARNING] 2025-02-20 08:14:42,345 log - Forbidden: /aplicatie_exemplu/add-product/
[WARNING] 2025-02-20 08:14:42,826 log - Forbidden: /aplicatie_exemplu/add-product/
[WARNING] 2025-02-20 08:14:48,744 log - Forbidden: /aplicatie_exemplu/add-product/
[WARNING] 2025-02-20 08:14:51,122 log - Forbidden: /aplicatie_exemplu/add-product/
[WARNING] 2025-02-20 08:15:00,053 log - Forbidden: /aplicatie_exemplu/add-product/
[WARNING] 2025-02-20 08:37:55,767 log - Forbidden (CSRF token from POST incorrect.): /aplicatie_exemplu/login/
[WARNING] 2025-02-20 08:37:55,767 basehttp - "POST /aplicatie_exemplu/login/ HTTP/1.1" 403 2506
[WARNING] 2025-02-20 08:37:57,505 log - Forbidden (CSRF token from POST incorrect.): /aplicatie_exemplu/login/
[WARNING] 2025-02-20 08:37:57,505 basehttp - "POST /aplicatie_exemplu/login/ HTTP/1.1" 403 2506
[ERROR] 2025-02-20 08:48:09,941 log - Internal Server Error: /aplicatie_exemplu/register/
Traceback (most recent call last):
  File "C:\Users\Maryo\virtualEnv\venv1\Lib\site-packages\django\db\backends\utils.py", line 105, in _execute
    return self.cursor.execute(sql, params)
           ^^^^^^^^^^^^^^^^^^^^^^^^^^^^^^^^
psycopg2.errors.UniqueViolation: duplicate key value violates unique constraint "custom_user_phone_number_key"
DETAIL:  Key (phone_number)=(0728646900) already exists.


The above exception was the direct cause of the following exception:

Traceback (most recent call last):
  File "C:\Users\Maryo\virtualEnv\venv1\Lib\site-packages\django\core\handlers\exception.py", line 55, in inner
    response = get_response(request)
               ^^^^^^^^^^^^^^^^^^^^^
  File "C:\Users\Maryo\virtualEnv\venv1\Lib\site-packages\django\core\handlers\base.py", line 197, in _get_response
    response = wrapped_callback(request, *callback_args, **callback_kwargs)
               ^^^^^^^^^^^^^^^^^^^^^^^^^^^^^^^^^^^^^^^^^^^^^^^^^^^^^^^^^^^^
  File "C:\Users\Maryo\proiectDjangolaBune\aplicatie_exemplu\views.py", line 157, in register
    user.save()
  File "C:\Users\Maryo\virtualEnv\venv1\Lib\site-packages\django\contrib\auth\base_user.py", line 62, in save
    super().save(*args, **kwargs)
  File "C:\Users\Maryo\virtualEnv\venv1\Lib\site-packages\django\db\models\base.py", line 892, in save
    self.save_base(
  File "C:\Users\Maryo\virtualEnv\venv1\Lib\site-packages\django\db\models\base.py", line 998, in save_base
    updated = self._save_table(
              ^^^^^^^^^^^^^^^^^
  File "C:\Users\Maryo\virtualEnv\venv1\Lib\site-packages\django\db\models\base.py", line 1161, in _save_table
    results = self._do_insert(
              ^^^^^^^^^^^^^^^^
  File "C:\Users\Maryo\virtualEnv\venv1\Lib\site-packages\django\db\models\base.py", line 1202, in _do_insert
    return manager._insert(
           ^^^^^^^^^^^^^^^^
  File "C:\Users\Maryo\virtualEnv\venv1\Lib\site-packages\django\db\models\manager.py", line 87, in manager_method
    return getattr(self.get_queryset(), name)(*args, **kwargs)
           ^^^^^^^^^^^^^^^^^^^^^^^^^^^^^^^^^^^^^^^^^^^^^^^^^^^
  File "C:\Users\Maryo\virtualEnv\venv1\Lib\site-packages\django\db\models\query.py", line 1847, in _insert
    return query.get_compiler(using=using).execute_sql(returning_fields)
           ^^^^^^^^^^^^^^^^^^^^^^^^^^^^^^^^^^^^^^^^^^^^^^^^^^^^^^^^^^^^^
  File "C:\Users\Maryo\virtualEnv\venv1\Lib\site-packages\django\db\models\sql\compiler.py", line 1836, in execute_sql
    cursor.execute(sql, params)
  File "C:\Users\Maryo\virtualEnv\venv1\Lib\site-packages\django\db\backends\utils.py", line 122, in execute
    return super().execute(sql, params)
           ^^^^^^^^^^^^^^^^^^^^^^^^^^^^
  File "C:\Users\Maryo\virtualEnv\venv1\Lib\site-packages\django\db\backends\utils.py", line 79, in execute
    return self._execute_with_wrappers(
           ^^^^^^^^^^^^^^^^^^^^^^^^^^^^
  File "C:\Users\Maryo\virtualEnv\venv1\Lib\site-packages\django\db\backends\utils.py", line 92, in _execute_with_wrappers
    return executor(sql, params, many, context)
           ^^^^^^^^^^^^^^^^^^^^^^^^^^^^^^^^^^^^
  File "C:\Users\Maryo\virtualEnv\venv1\Lib\site-packages\django\db\backends\utils.py", line 100, in _execute
    with self.db.wrap_database_errors:
  File "C:\Users\Maryo\virtualEnv\venv1\Lib\site-packages\django\db\utils.py", line 91, in __exit__
    raise dj_exc_value.with_traceback(traceback) from exc_value
  File "C:\Users\Maryo\virtualEnv\venv1\Lib\site-packages\django\db\backends\utils.py", line 105, in _execute
    return self.cursor.execute(sql, params)
           ^^^^^^^^^^^^^^^^^^^^^^^^^^^^^^^^
django.db.utils.IntegrityError: duplicate key value violates unique constraint "custom_user_phone_number_key"
DETAIL:  Key (phone_number)=(0728646900) already exists.

[ERROR] 2025-02-20 08:48:09,950 basehttp - "POST /aplicatie_exemplu/register/ HTTP/1.1" 500 157360
[ERROR] 2025-02-20 08:48:22,236 log - Internal Server Error: /aplicatie_exemplu/register/
Traceback (most recent call last):
  File "C:\Users\Maryo\virtualEnv\venv1\Lib\site-packages\django\db\backends\utils.py", line 105, in _execute
    return self.cursor.execute(sql, params)
           ^^^^^^^^^^^^^^^^^^^^^^^^^^^^^^^^
psycopg2.errors.UniqueViolation: duplicate key value violates unique constraint "custom_user_username_key"
DETAIL:  Key (username)=(maryo100) already exists.


The above exception was the direct cause of the following exception:

Traceback (most recent call last):
  File "C:\Users\Maryo\virtualEnv\venv1\Lib\site-packages\django\core\handlers\exception.py", line 55, in inner
    response = get_response(request)
               ^^^^^^^^^^^^^^^^^^^^^
  File "C:\Users\Maryo\virtualEnv\venv1\Lib\site-packages\django\core\handlers\base.py", line 197, in _get_response
    response = wrapped_callback(request, *callback_args, **callback_kwargs)
               ^^^^^^^^^^^^^^^^^^^^^^^^^^^^^^^^^^^^^^^^^^^^^^^^^^^^^^^^^^^^
  File "C:\Users\Maryo\proiectDjangolaBune\aplicatie_exemplu\views.py", line 157, in register
    user.save()
  File "C:\Users\Maryo\virtualEnv\venv1\Lib\site-packages\django\contrib\auth\base_user.py", line 62, in save
    super().save(*args, **kwargs)
  File "C:\Users\Maryo\virtualEnv\venv1\Lib\site-packages\django\db\models\base.py", line 892, in save
    self.save_base(
  File "C:\Users\Maryo\virtualEnv\venv1\Lib\site-packages\django\db\models\base.py", line 998, in save_base
    updated = self._save_table(
              ^^^^^^^^^^^^^^^^^
  File "C:\Users\Maryo\virtualEnv\venv1\Lib\site-packages\django\db\models\base.py", line 1161, in _save_table
    results = self._do_insert(
              ^^^^^^^^^^^^^^^^
  File "C:\Users\Maryo\virtualEnv\venv1\Lib\site-packages\django\db\models\base.py", line 1202, in _do_insert
    return manager._insert(
           ^^^^^^^^^^^^^^^^
  File "C:\Users\Maryo\virtualEnv\venv1\Lib\site-packages\django\db\models\manager.py", line 87, in manager_method
    return getattr(self.get_queryset(), name)(*args, **kwargs)
           ^^^^^^^^^^^^^^^^^^^^^^^^^^^^^^^^^^^^^^^^^^^^^^^^^^^
  File "C:\Users\Maryo\virtualEnv\venv1\Lib\site-packages\django\db\models\query.py", line 1847, in _insert
    return query.get_compiler(using=using).execute_sql(returning_fields)
           ^^^^^^^^^^^^^^^^^^^^^^^^^^^^^^^^^^^^^^^^^^^^^^^^^^^^^^^^^^^^^
  File "C:\Users\Maryo\virtualEnv\venv1\Lib\site-packages\django\db\models\sql\compiler.py", line 1836, in execute_sql
    cursor.execute(sql, params)
  File "C:\Users\Maryo\virtualEnv\venv1\Lib\site-packages\django\db\backends\utils.py", line 122, in execute
    return super().execute(sql, params)
           ^^^^^^^^^^^^^^^^^^^^^^^^^^^^
  File "C:\Users\Maryo\virtualEnv\venv1\Lib\site-packages\django\db\backends\utils.py", line 79, in execute
    return self._execute_with_wrappers(
           ^^^^^^^^^^^^^^^^^^^^^^^^^^^^
  File "C:\Users\Maryo\virtualEnv\venv1\Lib\site-packages\django\db\backends\utils.py", line 92, in _execute_with_wrappers
    return executor(sql, params, many, context)
           ^^^^^^^^^^^^^^^^^^^^^^^^^^^^^^^^^^^^
  File "C:\Users\Maryo\virtualEnv\venv1\Lib\site-packages\django\db\backends\utils.py", line 100, in _execute
    with self.db.wrap_database_errors:
  File "C:\Users\Maryo\virtualEnv\venv1\Lib\site-packages\django\db\utils.py", line 91, in __exit__
    raise dj_exc_value.with_traceback(traceback) from exc_value
  File "C:\Users\Maryo\virtualEnv\venv1\Lib\site-packages\django\db\backends\utils.py", line 105, in _execute
    return self.cursor.execute(sql, params)
           ^^^^^^^^^^^^^^^^^^^^^^^^^^^^^^^^
django.db.utils.IntegrityError: duplicate key value violates unique constraint "custom_user_username_key"
DETAIL:  Key (username)=(maryo100) already exists.

[ERROR] 2025-02-20 08:48:22,243 basehttp - "POST /aplicatie_exemplu/register/ HTTP/1.1" 500 157301
[ERROR] 2025-02-20 08:48:22,298 log - Internal Server Error: /aplicatie_exemplu/register/
Traceback (most recent call last):
  File "C:\Users\Maryo\virtualEnv\venv1\Lib\site-packages\django\db\backends\utils.py", line 105, in _execute
    return self.cursor.execute(sql, params)
           ^^^^^^^^^^^^^^^^^^^^^^^^^^^^^^^^
psycopg2.errors.UniqueViolation: duplicate key value violates unique constraint "custom_user_username_key"
DETAIL:  Key (username)=(maryo100) already exists.


The above exception was the direct cause of the following exception:

Traceback (most recent call last):
  File "C:\Users\Maryo\virtualEnv\venv1\Lib\site-packages\django\core\handlers\exception.py", line 55, in inner
    response = get_response(request)
               ^^^^^^^^^^^^^^^^^^^^^
  File "C:\Users\Maryo\virtualEnv\venv1\Lib\site-packages\django\core\handlers\base.py", line 197, in _get_response
    response = wrapped_callback(request, *callback_args, **callback_kwargs)
               ^^^^^^^^^^^^^^^^^^^^^^^^^^^^^^^^^^^^^^^^^^^^^^^^^^^^^^^^^^^^
  File "C:\Users\Maryo\proiectDjangolaBune\aplicatie_exemplu\views.py", line 157, in register
    user.save()
  File "C:\Users\Maryo\virtualEnv\venv1\Lib\site-packages\django\contrib\auth\base_user.py", line 62, in save
    super().save(*args, **kwargs)
  File "C:\Users\Maryo\virtualEnv\venv1\Lib\site-packages\django\db\models\base.py", line 892, in save
    self.save_base(
  File "C:\Users\Maryo\virtualEnv\venv1\Lib\site-packages\django\db\models\base.py", line 998, in save_base
    updated = self._save_table(
              ^^^^^^^^^^^^^^^^^
  File "C:\Users\Maryo\virtualEnv\venv1\Lib\site-packages\django\db\models\base.py", line 1161, in _save_table
    results = self._do_insert(
              ^^^^^^^^^^^^^^^^
  File "C:\Users\Maryo\virtualEnv\venv1\Lib\site-packages\django\db\models\base.py", line 1202, in _do_insert
    return manager._insert(
           ^^^^^^^^^^^^^^^^
  File "C:\Users\Maryo\virtualEnv\venv1\Lib\site-packages\django\db\models\manager.py", line 87, in manager_method
    return getattr(self.get_queryset(), name)(*args, **kwargs)
           ^^^^^^^^^^^^^^^^^^^^^^^^^^^^^^^^^^^^^^^^^^^^^^^^^^^
  File "C:\Users\Maryo\virtualEnv\venv1\Lib\site-packages\django\db\models\query.py", line 1847, in _insert
    return query.get_compiler(using=using).execute_sql(returning_fields)
           ^^^^^^^^^^^^^^^^^^^^^^^^^^^^^^^^^^^^^^^^^^^^^^^^^^^^^^^^^^^^^
  File "C:\Users\Maryo\virtualEnv\venv1\Lib\site-packages\django\db\models\sql\compiler.py", line 1836, in execute_sql
    cursor.execute(sql, params)
  File "C:\Users\Maryo\virtualEnv\venv1\Lib\site-packages\django\db\backends\utils.py", line 122, in execute
    return super().execute(sql, params)
           ^^^^^^^^^^^^^^^^^^^^^^^^^^^^
  File "C:\Users\Maryo\virtualEnv\venv1\Lib\site-packages\django\db\backends\utils.py", line 79, in execute
    return self._execute_with_wrappers(
           ^^^^^^^^^^^^^^^^^^^^^^^^^^^^
  File "C:\Users\Maryo\virtualEnv\venv1\Lib\site-packages\django\db\backends\utils.py", line 92, in _execute_with_wrappers
    return executor(sql, params, many, context)
           ^^^^^^^^^^^^^^^^^^^^^^^^^^^^^^^^^^^^
  File "C:\Users\Maryo\virtualEnv\venv1\Lib\site-packages\django\db\backends\utils.py", line 100, in _execute
    with self.db.wrap_database_errors:
  File "C:\Users\Maryo\virtualEnv\venv1\Lib\site-packages\django\db\utils.py", line 91, in __exit__
    raise dj_exc_value.with_traceback(traceback) from exc_value
  File "C:\Users\Maryo\virtualEnv\venv1\Lib\site-packages\django\db\backends\utils.py", line 105, in _execute
    return self.cursor.execute(sql, params)
           ^^^^^^^^^^^^^^^^^^^^^^^^^^^^^^^^
django.db.utils.IntegrityError: duplicate key value violates unique constraint "custom_user_username_key"
DETAIL:  Key (username)=(maryo100) already exists.

[ERROR] 2025-02-20 08:48:22,306 basehttp - "POST /aplicatie_exemplu/register/ HTTP/1.1" 500 157293
[ERROR] 2025-02-20 08:48:22,378 log - Internal Server Error: /aplicatie_exemplu/register/
Traceback (most recent call last):
  File "C:\Users\Maryo\virtualEnv\venv1\Lib\site-packages\django\db\backends\utils.py", line 105, in _execute
    return self.cursor.execute(sql, params)
           ^^^^^^^^^^^^^^^^^^^^^^^^^^^^^^^^
psycopg2.errors.UniqueViolation: duplicate key value violates unique constraint "custom_user_username_key"
DETAIL:  Key (username)=(maryo100) already exists.


The above exception was the direct cause of the following exception:

Traceback (most recent call last):
  File "C:\Users\Maryo\virtualEnv\venv1\Lib\site-packages\django\core\handlers\exception.py", line 55, in inner
    response = get_response(request)
               ^^^^^^^^^^^^^^^^^^^^^
  File "C:\Users\Maryo\virtualEnv\venv1\Lib\site-packages\django\core\handlers\base.py", line 197, in _get_response
    response = wrapped_callback(request, *callback_args, **callback_kwargs)
               ^^^^^^^^^^^^^^^^^^^^^^^^^^^^^^^^^^^^^^^^^^^^^^^^^^^^^^^^^^^^
  File "C:\Users\Maryo\proiectDjangolaBune\aplicatie_exemplu\views.py", line 157, in register
    user.save()
  File "C:\Users\Maryo\virtualEnv\venv1\Lib\site-packages\django\contrib\auth\base_user.py", line 62, in save
    super().save(*args, **kwargs)
  File "C:\Users\Maryo\virtualEnv\venv1\Lib\site-packages\django\db\models\base.py", line 892, in save
    self.save_base(
  File "C:\Users\Maryo\virtualEnv\venv1\Lib\site-packages\django\db\models\base.py", line 998, in save_base
    updated = self._save_table(
              ^^^^^^^^^^^^^^^^^
  File "C:\Users\Maryo\virtualEnv\venv1\Lib\site-packages\django\db\models\base.py", line 1161, in _save_table
    results = self._do_insert(
              ^^^^^^^^^^^^^^^^
  File "C:\Users\Maryo\virtualEnv\venv1\Lib\site-packages\django\db\models\base.py", line 1202, in _do_insert
    return manager._insert(
           ^^^^^^^^^^^^^^^^
  File "C:\Users\Maryo\virtualEnv\venv1\Lib\site-packages\django\db\models\manager.py", line 87, in manager_method
    return getattr(self.get_queryset(), name)(*args, **kwargs)
           ^^^^^^^^^^^^^^^^^^^^^^^^^^^^^^^^^^^^^^^^^^^^^^^^^^^
  File "C:\Users\Maryo\virtualEnv\venv1\Lib\site-packages\django\db\models\query.py", line 1847, in _insert
    return query.get_compiler(using=using).execute_sql(returning_fields)
           ^^^^^^^^^^^^^^^^^^^^^^^^^^^^^^^^^^^^^^^^^^^^^^^^^^^^^^^^^^^^^
  File "C:\Users\Maryo\virtualEnv\venv1\Lib\site-packages\django\db\models\sql\compiler.py", line 1836, in execute_sql
    cursor.execute(sql, params)
  File "C:\Users\Maryo\virtualEnv\venv1\Lib\site-packages\django\db\backends\utils.py", line 122, in execute
    return super().execute(sql, params)
           ^^^^^^^^^^^^^^^^^^^^^^^^^^^^
  File "C:\Users\Maryo\virtualEnv\venv1\Lib\site-packages\django\db\backends\utils.py", line 79, in execute
    return self._execute_with_wrappers(
           ^^^^^^^^^^^^^^^^^^^^^^^^^^^^
  File "C:\Users\Maryo\virtualEnv\venv1\Lib\site-packages\django\db\backends\utils.py", line 92, in _execute_with_wrappers
    return executor(sql, params, many, context)
           ^^^^^^^^^^^^^^^^^^^^^^^^^^^^^^^^^^^^
  File "C:\Users\Maryo\virtualEnv\venv1\Lib\site-packages\django\db\backends\utils.py", line 100, in _execute
    with self.db.wrap_database_errors:
  File "C:\Users\Maryo\virtualEnv\venv1\Lib\site-packages\django\db\utils.py", line 91, in __exit__
    raise dj_exc_value.with_traceback(traceback) from exc_value
  File "C:\Users\Maryo\virtualEnv\venv1\Lib\site-packages\django\db\backends\utils.py", line 105, in _execute
    return self.cursor.execute(sql, params)
           ^^^^^^^^^^^^^^^^^^^^^^^^^^^^^^^^
django.db.utils.IntegrityError: duplicate key value violates unique constraint "custom_user_username_key"
DETAIL:  Key (username)=(maryo100) already exists.

[ERROR] 2025-02-20 08:48:22,381 basehttp - "POST /aplicatie_exemplu/register/ HTTP/1.1" 500 157285
[ERROR] 2025-02-20 08:48:32,653 log - Internal Server Error: /aplicatie_exemplu/register/
Traceback (most recent call last):
  File "C:\Users\Maryo\virtualEnv\venv1\Lib\site-packages\django\db\backends\utils.py", line 105, in _execute
    return self.cursor.execute(sql, params)
           ^^^^^^^^^^^^^^^^^^^^^^^^^^^^^^^^
psycopg2.errors.UniqueViolation: duplicate key value violates unique constraint "custom_user_phone_number_key"
DETAIL:  Key (phone_number)=(0732156522) already exists.


The above exception was the direct cause of the following exception:

Traceback (most recent call last):
  File "C:\Users\Maryo\virtualEnv\venv1\Lib\site-packages\django\core\handlers\exception.py", line 55, in inner
    response = get_response(request)
               ^^^^^^^^^^^^^^^^^^^^^
  File "C:\Users\Maryo\virtualEnv\venv1\Lib\site-packages\django\core\handlers\base.py", line 197, in _get_response
    response = wrapped_callback(request, *callback_args, **callback_kwargs)
               ^^^^^^^^^^^^^^^^^^^^^^^^^^^^^^^^^^^^^^^^^^^^^^^^^^^^^^^^^^^^
  File "C:\Users\Maryo\proiectDjangolaBune\aplicatie_exemplu\views.py", line 157, in register
    user.save()
  File "C:\Users\Maryo\virtualEnv\venv1\Lib\site-packages\django\contrib\auth\base_user.py", line 62, in save
    super().save(*args, **kwargs)
  File "C:\Users\Maryo\virtualEnv\venv1\Lib\site-packages\django\db\models\base.py", line 892, in save
    self.save_base(
  File "C:\Users\Maryo\virtualEnv\venv1\Lib\site-packages\django\db\models\base.py", line 998, in save_base
    updated = self._save_table(
              ^^^^^^^^^^^^^^^^^
  File "C:\Users\Maryo\virtualEnv\venv1\Lib\site-packages\django\db\models\base.py", line 1161, in _save_table
    results = self._do_insert(
              ^^^^^^^^^^^^^^^^
  File "C:\Users\Maryo\virtualEnv\venv1\Lib\site-packages\django\db\models\base.py", line 1202, in _do_insert
    return manager._insert(
           ^^^^^^^^^^^^^^^^
  File "C:\Users\Maryo\virtualEnv\venv1\Lib\site-packages\django\db\models\manager.py", line 87, in manager_method
    return getattr(self.get_queryset(), name)(*args, **kwargs)
           ^^^^^^^^^^^^^^^^^^^^^^^^^^^^^^^^^^^^^^^^^^^^^^^^^^^
  File "C:\Users\Maryo\virtualEnv\venv1\Lib\site-packages\django\db\models\query.py", line 1847, in _insert
    return query.get_compiler(using=using).execute_sql(returning_fields)
           ^^^^^^^^^^^^^^^^^^^^^^^^^^^^^^^^^^^^^^^^^^^^^^^^^^^^^^^^^^^^^
  File "C:\Users\Maryo\virtualEnv\venv1\Lib\site-packages\django\db\models\sql\compiler.py", line 1836, in execute_sql
    cursor.execute(sql, params)
  File "C:\Users\Maryo\virtualEnv\venv1\Lib\site-packages\django\db\backends\utils.py", line 122, in execute
    return super().execute(sql, params)
           ^^^^^^^^^^^^^^^^^^^^^^^^^^^^
  File "C:\Users\Maryo\virtualEnv\venv1\Lib\site-packages\django\db\backends\utils.py", line 79, in execute
    return self._execute_with_wrappers(
           ^^^^^^^^^^^^^^^^^^^^^^^^^^^^
  File "C:\Users\Maryo\virtualEnv\venv1\Lib\site-packages\django\db\backends\utils.py", line 92, in _execute_with_wrappers
    return executor(sql, params, many, context)
           ^^^^^^^^^^^^^^^^^^^^^^^^^^^^^^^^^^^^
  File "C:\Users\Maryo\virtualEnv\venv1\Lib\site-packages\django\db\backends\utils.py", line 100, in _execute
    with self.db.wrap_database_errors:
  File "C:\Users\Maryo\virtualEnv\venv1\Lib\site-packages\django\db\utils.py", line 91, in __exit__
    raise dj_exc_value.with_traceback(traceback) from exc_value
  File "C:\Users\Maryo\virtualEnv\venv1\Lib\site-packages\django\db\backends\utils.py", line 105, in _execute
    return self.cursor.execute(sql, params)
           ^^^^^^^^^^^^^^^^^^^^^^^^^^^^^^^^
django.db.utils.IntegrityError: duplicate key value violates unique constraint "custom_user_phone_number_key"
DETAIL:  Key (phone_number)=(0732156522) already exists.

[ERROR] 2025-02-20 08:48:32,663 basehttp - "POST /aplicatie_exemplu/register/ HTTP/1.1" 500 157318
[ERROR] 2025-02-20 08:48:32,726 log - Internal Server Error: /aplicatie_exemplu/register/
Traceback (most recent call last):
  File "C:\Users\Maryo\virtualEnv\venv1\Lib\site-packages\django\db\backends\utils.py", line 105, in _execute
    return self.cursor.execute(sql, params)
           ^^^^^^^^^^^^^^^^^^^^^^^^^^^^^^^^
psycopg2.errors.UniqueViolation: duplicate key value violates unique constraint "custom_user_phone_number_key"
DETAIL:  Key (phone_number)=(0732156522) already exists.


The above exception was the direct cause of the following exception:

Traceback (most recent call last):
  File "C:\Users\Maryo\virtualEnv\venv1\Lib\site-packages\django\core\handlers\exception.py", line 55, in inner
    response = get_response(request)
               ^^^^^^^^^^^^^^^^^^^^^
  File "C:\Users\Maryo\virtualEnv\venv1\Lib\site-packages\django\core\handlers\base.py", line 197, in _get_response
    response = wrapped_callback(request, *callback_args, **callback_kwargs)
               ^^^^^^^^^^^^^^^^^^^^^^^^^^^^^^^^^^^^^^^^^^^^^^^^^^^^^^^^^^^^
  File "C:\Users\Maryo\proiectDjangolaBune\aplicatie_exemplu\views.py", line 157, in register
    user.save()
  File "C:\Users\Maryo\virtualEnv\venv1\Lib\site-packages\django\contrib\auth\base_user.py", line 62, in save
    super().save(*args, **kwargs)
  File "C:\Users\Maryo\virtualEnv\venv1\Lib\site-packages\django\db\models\base.py", line 892, in save
    self.save_base(
  File "C:\Users\Maryo\virtualEnv\venv1\Lib\site-packages\django\db\models\base.py", line 998, in save_base
    updated = self._save_table(
              ^^^^^^^^^^^^^^^^^
  File "C:\Users\Maryo\virtualEnv\venv1\Lib\site-packages\django\db\models\base.py", line 1161, in _save_table
    results = self._do_insert(
              ^^^^^^^^^^^^^^^^
  File "C:\Users\Maryo\virtualEnv\venv1\Lib\site-packages\django\db\models\base.py", line 1202, in _do_insert
    return manager._insert(
           ^^^^^^^^^^^^^^^^
  File "C:\Users\Maryo\virtualEnv\venv1\Lib\site-packages\django\db\models\manager.py", line 87, in manager_method
    return getattr(self.get_queryset(), name)(*args, **kwargs)
           ^^^^^^^^^^^^^^^^^^^^^^^^^^^^^^^^^^^^^^^^^^^^^^^^^^^
  File "C:\Users\Maryo\virtualEnv\venv1\Lib\site-packages\django\db\models\query.py", line 1847, in _insert
    return query.get_compiler(using=using).execute_sql(returning_fields)
           ^^^^^^^^^^^^^^^^^^^^^^^^^^^^^^^^^^^^^^^^^^^^^^^^^^^^^^^^^^^^^
  File "C:\Users\Maryo\virtualEnv\venv1\Lib\site-packages\django\db\models\sql\compiler.py", line 1836, in execute_sql
    cursor.execute(sql, params)
  File "C:\Users\Maryo\virtualEnv\venv1\Lib\site-packages\django\db\backends\utils.py", line 122, in execute
    return super().execute(sql, params)
           ^^^^^^^^^^^^^^^^^^^^^^^^^^^^
  File "C:\Users\Maryo\virtualEnv\venv1\Lib\site-packages\django\db\backends\utils.py", line 79, in execute
    return self._execute_with_wrappers(
           ^^^^^^^^^^^^^^^^^^^^^^^^^^^^
  File "C:\Users\Maryo\virtualEnv\venv1\Lib\site-packages\django\db\backends\utils.py", line 92, in _execute_with_wrappers
    return executor(sql, params, many, context)
           ^^^^^^^^^^^^^^^^^^^^^^^^^^^^^^^^^^^^
  File "C:\Users\Maryo\virtualEnv\venv1\Lib\site-packages\django\db\backends\utils.py", line 100, in _execute
    with self.db.wrap_database_errors:
  File "C:\Users\Maryo\virtualEnv\venv1\Lib\site-packages\django\db\utils.py", line 91, in __exit__
    raise dj_exc_value.with_traceback(traceback) from exc_value
  File "C:\Users\Maryo\virtualEnv\venv1\Lib\site-packages\django\db\backends\utils.py", line 105, in _execute
    return self.cursor.execute(sql, params)
           ^^^^^^^^^^^^^^^^^^^^^^^^^^^^^^^^
django.db.utils.IntegrityError: duplicate key value violates unique constraint "custom_user_phone_number_key"
DETAIL:  Key (phone_number)=(0732156522) already exists.

[ERROR] 2025-02-20 08:48:32,729 basehttp - "POST /aplicatie_exemplu/register/ HTTP/1.1" 500 157328
[ERROR] 2025-02-20 08:48:32,878 log - Internal Server Error: /aplicatie_exemplu/register/
Traceback (most recent call last):
  File "C:\Users\Maryo\virtualEnv\venv1\Lib\site-packages\django\db\backends\utils.py", line 105, in _execute
    return self.cursor.execute(sql, params)
           ^^^^^^^^^^^^^^^^^^^^^^^^^^^^^^^^
psycopg2.errors.UniqueViolation: duplicate key value violates unique constraint "custom_user_phone_number_key"
DETAIL:  Key (phone_number)=(0732156522) already exists.


The above exception was the direct cause of the following exception:

Traceback (most recent call last):
  File "C:\Users\Maryo\virtualEnv\venv1\Lib\site-packages\django\core\handlers\exception.py", line 55, in inner
    response = get_response(request)
               ^^^^^^^^^^^^^^^^^^^^^
  File "C:\Users\Maryo\virtualEnv\venv1\Lib\site-packages\django\core\handlers\base.py", line 197, in _get_response
    response = wrapped_callback(request, *callback_args, **callback_kwargs)
               ^^^^^^^^^^^^^^^^^^^^^^^^^^^^^^^^^^^^^^^^^^^^^^^^^^^^^^^^^^^^
  File "C:\Users\Maryo\proiectDjangolaBune\aplicatie_exemplu\views.py", line 157, in register
    user.save()
  File "C:\Users\Maryo\virtualEnv\venv1\Lib\site-packages\django\contrib\auth\base_user.py", line 62, in save
    super().save(*args, **kwargs)
  File "C:\Users\Maryo\virtualEnv\venv1\Lib\site-packages\django\db\models\base.py", line 892, in save
    self.save_base(
  File "C:\Users\Maryo\virtualEnv\venv1\Lib\site-packages\django\db\models\base.py", line 998, in save_base
    updated = self._save_table(
              ^^^^^^^^^^^^^^^^^
  File "C:\Users\Maryo\virtualEnv\venv1\Lib\site-packages\django\db\models\base.py", line 1161, in _save_table
    results = self._do_insert(
              ^^^^^^^^^^^^^^^^
  File "C:\Users\Maryo\virtualEnv\venv1\Lib\site-packages\django\db\models\base.py", line 1202, in _do_insert
    return manager._insert(
           ^^^^^^^^^^^^^^^^
  File "C:\Users\Maryo\virtualEnv\venv1\Lib\site-packages\django\db\models\manager.py", line 87, in manager_method
    return getattr(self.get_queryset(), name)(*args, **kwargs)
           ^^^^^^^^^^^^^^^^^^^^^^^^^^^^^^^^^^^^^^^^^^^^^^^^^^^
  File "C:\Users\Maryo\virtualEnv\venv1\Lib\site-packages\django\db\models\query.py", line 1847, in _insert
    return query.get_compiler(using=using).execute_sql(returning_fields)
           ^^^^^^^^^^^^^^^^^^^^^^^^^^^^^^^^^^^^^^^^^^^^^^^^^^^^^^^^^^^^^
  File "C:\Users\Maryo\virtualEnv\venv1\Lib\site-packages\django\db\models\sql\compiler.py", line 1836, in execute_sql
    cursor.execute(sql, params)
  File "C:\Users\Maryo\virtualEnv\venv1\Lib\site-packages\django\db\backends\utils.py", line 122, in execute
    return super().execute(sql, params)
           ^^^^^^^^^^^^^^^^^^^^^^^^^^^^
  File "C:\Users\Maryo\virtualEnv\venv1\Lib\site-packages\django\db\backends\utils.py", line 79, in execute
    return self._execute_with_wrappers(
           ^^^^^^^^^^^^^^^^^^^^^^^^^^^^
  File "C:\Users\Maryo\virtualEnv\venv1\Lib\site-packages\django\db\backends\utils.py", line 92, in _execute_with_wrappers
    return executor(sql, params, many, context)
           ^^^^^^^^^^^^^^^^^^^^^^^^^^^^^^^^^^^^
  File "C:\Users\Maryo\virtualEnv\venv1\Lib\site-packages\django\db\backends\utils.py", line 100, in _execute
    with self.db.wrap_database_errors:
  File "C:\Users\Maryo\virtualEnv\venv1\Lib\site-packages\django\db\utils.py", line 91, in __exit__
    raise dj_exc_value.with_traceback(traceback) from exc_value
  File "C:\Users\Maryo\virtualEnv\venv1\Lib\site-packages\django\db\backends\utils.py", line 105, in _execute
    return self.cursor.execute(sql, params)
           ^^^^^^^^^^^^^^^^^^^^^^^^^^^^^^^^
django.db.utils.IntegrityError: duplicate key value violates unique constraint "custom_user_phone_number_key"
DETAIL:  Key (phone_number)=(0732156522) already exists.

[ERROR] 2025-02-20 08:48:32,880 basehttp - "POST /aplicatie_exemplu/register/ HTTP/1.1" 500 157352
[ERROR] 2025-02-20 08:49:58,631 log - Internal Server Error: /aplicatie_exemplu/register/
Traceback (most recent call last):
  File "C:\Users\Maryo\virtualEnv\venv1\Lib\site-packages\django\db\backends\utils.py", line 105, in _execute
    return self.cursor.execute(sql, params)
           ^^^^^^^^^^^^^^^^^^^^^^^^^^^^^^^^
psycopg2.errors.UniqueViolation: duplicate key value violates unique constraint "custom_user_username_key"
DETAIL:  Key (username)=(maryo092) already exists.


The above exception was the direct cause of the following exception:

Traceback (most recent call last):
  File "C:\Users\Maryo\virtualEnv\venv1\Lib\site-packages\django\core\handlers\exception.py", line 55, in inner
    response = get_response(request)
               ^^^^^^^^^^^^^^^^^^^^^
  File "C:\Users\Maryo\virtualEnv\venv1\Lib\site-packages\django\core\handlers\base.py", line 197, in _get_response
    response = wrapped_callback(request, *callback_args, **callback_kwargs)
               ^^^^^^^^^^^^^^^^^^^^^^^^^^^^^^^^^^^^^^^^^^^^^^^^^^^^^^^^^^^^
  File "C:\Users\Maryo\proiectDjangolaBune\aplicatie_exemplu\views.py", line 157, in register
    user.save()
  File "C:\Users\Maryo\virtualEnv\venv1\Lib\site-packages\django\contrib\auth\base_user.py", line 62, in save
    super().save(*args, **kwargs)
  File "C:\Users\Maryo\virtualEnv\venv1\Lib\site-packages\django\db\models\base.py", line 892, in save
    self.save_base(
  File "C:\Users\Maryo\virtualEnv\venv1\Lib\site-packages\django\db\models\base.py", line 998, in save_base
    updated = self._save_table(
              ^^^^^^^^^^^^^^^^^
  File "C:\Users\Maryo\virtualEnv\venv1\Lib\site-packages\django\db\models\base.py", line 1161, in _save_table
    results = self._do_insert(
              ^^^^^^^^^^^^^^^^
  File "C:\Users\Maryo\virtualEnv\venv1\Lib\site-packages\django\db\models\base.py", line 1202, in _do_insert
    return manager._insert(
           ^^^^^^^^^^^^^^^^
  File "C:\Users\Maryo\virtualEnv\venv1\Lib\site-packages\django\db\models\manager.py", line 87, in manager_method
    return getattr(self.get_queryset(), name)(*args, **kwargs)
           ^^^^^^^^^^^^^^^^^^^^^^^^^^^^^^^^^^^^^^^^^^^^^^^^^^^
  File "C:\Users\Maryo\virtualEnv\venv1\Lib\site-packages\django\db\models\query.py", line 1847, in _insert
    return query.get_compiler(using=using).execute_sql(returning_fields)
           ^^^^^^^^^^^^^^^^^^^^^^^^^^^^^^^^^^^^^^^^^^^^^^^^^^^^^^^^^^^^^
  File "C:\Users\Maryo\virtualEnv\venv1\Lib\site-packages\django\db\models\sql\compiler.py", line 1836, in execute_sql
    cursor.execute(sql, params)
  File "C:\Users\Maryo\virtualEnv\venv1\Lib\site-packages\django\db\backends\utils.py", line 122, in execute
    return super().execute(sql, params)
           ^^^^^^^^^^^^^^^^^^^^^^^^^^^^
  File "C:\Users\Maryo\virtualEnv\venv1\Lib\site-packages\django\db\backends\utils.py", line 79, in execute
    return self._execute_with_wrappers(
           ^^^^^^^^^^^^^^^^^^^^^^^^^^^^
  File "C:\Users\Maryo\virtualEnv\venv1\Lib\site-packages\django\db\backends\utils.py", line 92, in _execute_with_wrappers
    return executor(sql, params, many, context)
           ^^^^^^^^^^^^^^^^^^^^^^^^^^^^^^^^^^^^
  File "C:\Users\Maryo\virtualEnv\venv1\Lib\site-packages\django\db\backends\utils.py", line 100, in _execute
    with self.db.wrap_database_errors:
  File "C:\Users\Maryo\virtualEnv\venv1\Lib\site-packages\django\db\utils.py", line 91, in __exit__
    raise dj_exc_value.with_traceback(traceback) from exc_value
  File "C:\Users\Maryo\virtualEnv\venv1\Lib\site-packages\django\db\backends\utils.py", line 105, in _execute
    return self.cursor.execute(sql, params)
           ^^^^^^^^^^^^^^^^^^^^^^^^^^^^^^^^
django.db.utils.IntegrityError: duplicate key value violates unique constraint "custom_user_username_key"
DETAIL:  Key (username)=(maryo092) already exists.

[ERROR] 2025-02-20 08:49:58,635 basehttp - "POST /aplicatie_exemplu/register/ HTTP/1.1" 500 157363
